Workbook

Sheet สรุปรวม
B2: สรุปผลการตรวจสุขภาพพนักงานประจำปี 2567
B3: รายละเอียดการตรวจ | C3: จำนวนผู้เข้ารับการตรวจ | D3: ปกติ | E3: ผิดปกติ | F3: %ผิดปกติ
B4: ตรวจสายตาทางอาชีวอนามัย | C4: 439 | D4: 81 | E4: 358 | F4: 81 | G4: %
B5: ตรวจไขมันในเลือด | C5: 450 | D5: 87 | E5: 363 | F5: 81 | G5: %
B6: ดัชนีมวลกาย | C6: 471 | D6: 111 | E6: 360 | F6: 76 | G6: %
B7: ตรวจสมรรถภาพการได้ยิน | C7: 435 | D7: 159 | E7: 276 | F7: 63 | G7: %
B8: ตรวจความสมบูรณ์ของเม็ดเลือด | C8: 418 | D8: 288 | E8: 130 | F8: 31 | G8: %
B9: ตรวจสารหนูในปัสสาวะ( Arsenic in Urine ) | C9: 13 | D9: 9 | E9: 4 | F9: 31 | G9: %
B10: ตรวจการทำงานของตับ | C10: 419 | D10: 327 | E10: 92 | F10: 22 | G10: %
B11: ตรวจน้ำตาลในเลือด | C11: 449 | D11: 370 | E11: 79 | F11: 18 | G11: %
B12: ตรวจปัสสาวะสมบูรณ์แบบ | C12: 432 | D12: 361 | E12: 71 | F12: 16 | G12: %
B13: ตรวจคลื่นไฟฟ้าหัวใจ | C13: 410 | D13: 347 | E13: 63 | F13: 15 | G13: %
B14: ตรวจวัดความดันโลหิต | C14: 471 | D14: 404 | E14: 67 | F14: 14 | G14: %
B15: ตรวจสมรรถภาพปอด | C15: 446 | D15: 384 | E15: 59 | F15: 13 | G15: %
... B35: ตรวจสารเมทิล เอทิล คีโตนในปัสสาวะ(Methyl Ethyl Ketone in Urine ) | C35: 21 | D35: 21 | E35: 0 | F35: 0 | G35: %

Sheet รายชื่อ
B4: รายชื่อพนักงานตรวจสุขภาพประจำปี 2567
B5: บ. ปูนซิเมนต์ไทย (ทุ่งสง) จำกัด / ตรวจสุขภาพ
B6: ลำดับ | C6: HN | D6: SCG Employee ID | E6: ชื่อ - สกุล | F6: วัน/เดือน/ปีเกิด | G6: อายุ | H6: ตำแหน่งงาน | I6: หน่วยงาน | J6: ส่วน (สำหรับพนักงาน) | K6: โปรแกรม
B7: 1 | C7: 14471-58 | D7: =VLOOKUP(C7,[1]รายชื่อ!$C:$D,2,0) -> 0150-020718 | E7: นาง กมลทิพย์ ขบวนสาร | F7: 07 มิ.ย. 2527 | G7: 40 | H7: พนักงานธุรการ | I7: Operations | J7: Operations | K7: รายการตรวจเพิ่มเติม บ.ปูนซิเมนต์ไทย (ทุ่งสง) / คัดกรองโรคมะเร็ง, ชุดคอร์สตรวจสุขภาพ SCG / พนักงาน (ปี67) โปรแกรม 9 (C1F1Uเหลือง1)
B8: 2 | C8: 165-57 | D8: 0150-020899 | E8: นาย กรณัฐพงษ์ เรืองระพีพรรณ | F8: 04 เม.ย. 2533 | G8: 34 | H8: #N/A | I8: #N/A | J8: #N/A | K8: ชุดคอร์สตรวจสุขภาพ SCG / พนักงาน (ปี67) โปรแกรม 7 (C1E1F1Uเหลือง1U)
B9: 3 | C9: 9043-49 | D9: =VLOOKUP(C9,[1]รายชื่อ!$C:$D,2,0) -> 0150-021664 | E9: น.ส. กฤติกา หมัดโส๊ะ | F9: 01 ม.ค. 2528 | G9: 39 | H9: พนักงานเทคโนโลยีสารสนเทศ | I9: เทคโนโลยีสารสนเทศ | J9: MD Office | K9: ชุดคอร์สตรวจสุขภาพ SCG / พนักงาน (ปี67) โปรแกรม 17 (C1F1Uเหลือง1)
B10: 4 | C10: 5101-50 | D10: =VLOOKUP(C10,[1]รายชื่อ!$C:$D,2,0) -> 0150-017521 | E10: นาย กฤษฎากรณ์ เดชะราช | F10: 18 มิ.ย. 2515 | G10: 52 | H10: Technical and Maintenance Planning Manager | I10: Plant Maintenance | J10: Maintenance Repair Overhaul - STS | K10: ชุดคอร์สตรวจสุขภาพ SCG / พนักงาน (ปี67) โปรแกรม 15 (C1E1F1Uหลือง1)
B11: 5 | C11: 13350-56 | D11: 0150-020934 | E11: นาย กฤษณรักษ์ รัตนะ | F11: 12 พ.ย. 2530 | G11: 36 | H11: พนักงานซ่อมบำรุงจักรกลหนัก | I11: ซ่อมบำรุงจักรกลหนัก | J11: Quarry | K11: ชุดคอร์สตรวจสุขภาพ SCG / พนักงาน (ปี67) โปรแกรม 1 (C1E1F1Uเหลือง1)
B12: 6 | C12: 20669-60 | D12: =VLOOKUP(C12,[1]รายชื่อ!$C:$D,2,0) -> 0150-019511 | E12: นาย กฤษดา หนูหอ | F12: 25 เม.ย. 2520 | G12: 47 | H12: Maintenance Overhaul and Consultancy Technician - Electrical | I12: Maintenance Overhaul and Consultancy - Electrical | J12: Maintenance Repair Overhaul - STS | K12: ชุดคอร์สตรวจสุขภาพ SCG / พนักงาน (ปี67) โปรแกรม 15 (C1E1F1Uหลือง1)
B13: 7 | C13: 20050-65 | D13: =VLOOKUP(C13,[1]รายชื่อ!$C:$D,2,0) -> 0150-021955 | E13: นาย กวิศ แซ่ตั้ง | F13: 01 ม.ค. 2535 | G13: 32 | H13: #N/A | I13: #N/A | J13: #N/A | K13: ชุดคอร์สตรวจสุขภาพ SCG / พนักงาน (ปี67) โปรแกรม 7 (C1E1F1Uเหลือง1U)
B14: 8 | C14: 11980-47 | D14: =VLOOKUP(C14,[1]รายชื่อ!$C:$D,2,0) -> 0150-014997 | E14: นาย ก้องทัย คุณโลก | F14: 17 มี.ค. 2512 | G14: 55 | H14: Mechanical Maintenance Manager – Clinker | I14: Plant Maintenance | J14: Maintenance Repair Overhaul - STS | K14: ชุดคอร์สตรวจสุขภาพ SCG / พนักงาน (ปี67) โปรแกรม 15 (C1E1F1Uหลือง1)
B15: 9 | C15: 443-50 | D15: =VLOOKUP(C15,[1]รายชื่อ!$C:$D,2,0) -> 0150-019471 | E15: นาย กัญจน์ภัสสรณ์ พรหมแสง | F15: 05 มิ.ย. 2519 | G15: 48 | H15: #N/A | I15: #N/A | J15: #N/A | K15: ชุดคอร์สตรวจสุขภาพ SCG / พนักงาน (ปี67) โปรแกรม 16 (C1E2F1Uเหลือง1Uแดง4)
B16: 10 | C16: 19597-49 | D16: =VLOOKUP(C16,[1]รายชื่อ!$C:$D,2,0) -> 0150-020267 | E16: น.ส. กัญธนัช ศรีโยธา | F16: 14 ต.ค. 2528 | G16: 38 | H16: BSE Assistant Manager-South Chain | I16: BSE South Chain | J16: BSE South Chain | K16: ชุดคอร์สตรวจสุขภาพ SCG / พนักงาน (ปี67) โปรแกรม 17 (C1F1Uเหลือง1)
B17: 11 | C17: 24355-61 | D17: =VLOOKUP(C17,[1]รายชื่อ!$C:$D,2,0) -> 0150-021198 | E17: นาง กาญจนา ลีลารุจนกุล | F17: 13 ต.ค. 2535 | G17: 31 | H17: BSE Operation Officer-STS | I17: BSE Operation - STS | J17: BSE Operation - STS | K17: ชุดคอร์สตรวจสุขภาพ SCG / พนักงาน (ปี67) โปรแกรม 17 (C1F1Uเหลือง1)
B18: 12 | C18: 11655-54 | D18: =VLOOKUP(C18,[1]รายชื่อ!$C:$D,2,0) -> 0150-020685 | E18: นาย ก้าน สิทธิวงศ์ | F18: 28 ก.ค. 2525 | G18: 41 | H18: พนักงานผลิตถุงกระดาษ | I18: ผลิตถุงกระดาษ | J18: Operations | K18: ชุดตรวจสุขภาพคู่สัญญา ปูน B (อายุ35-50 ปี), รายการตรวจเพิ่มเติม สำหรับลูกค้า คู่สัญญา (M) ( ตอบโจทย์ ตรงใจ ), รายการตรวจเพิ่มเติม บ.ปูนซิเมนต์ไทย (ทุ่งสง) / คัดกรองโรคมะเร็ง, ชุดคอร์สตรวจสุขภาพ SCG / พนักงาน (ปี67) โปรแกรม 8 (C1E1F1Uเหลือง1Uแดง1)
B19: 13 | C19: 4482-62 | D19: =VLOOKUP(C19,[1]รายชื่อ!$C:$D,2,0) -> 0150-020930 | E19: นาย กิตตินันท์ จันทกูล | F19: 27 ก.ย. 2534 | G19: 32 | H19: Mechanical Technician | I19: Plant Maintenance | J19: Maintenance Repair Overhaul - STS | K19: ชุดคอร์สตรวจสุขภาพ SCG / พนักงาน (ปี67) โปรแกรม 15 (C1E1F1Uหลือง1)
B20: 14 | C20: 16852-60 | D20: =VLOOKUP(C20,[1]รายชื่อ!$C:$D,2,0) -> 0150-021636 | E20: นาย กิตติพงศ์ ไพชำนาญ | F20: 04 มี.ค. 2535 | G20: 32 | H20: Engineer | I20: Maintenance Repair Overhaul - STS | J20: Maintenance Repair Overhaul - STS | K20: ชุดคอร์สตรวจสุขภาพ SCG / พนักงาน (ปี67) โปรแกรม 7 (C1E1F1Uเหลือง1U)
B21: 15 | C21: 22376-59 | D21: =VLOOKUP(C21,[1]รายชื่อ!$C:$D,2,0) -> 0150-020460 | E21: นาย กิตติพงศ์ สหกโร | F21: 30 เม.ย. 2530 | G21: 37 | H21: พนักงานควบคุมเครื่องย่อย | I21: ผลิตหินย่อยและหินก่อสร้าง | J21: Quarry | K21: ชุดตรวจสุขภาพคู่สัญญา ปูน B (อายุ35-50 ปี), ชุดคอร์สตรวจสุขภาพ SCG / พนักงาน (ปี67) โปรแกรม 7 (C1E1F1Uเหลือง1U)
B22: 16 | C22: 3969-43 | D22: =VLOOKUP(C22,[1]รายชื่อ!$C:$D,2,0) -> 0150-018588 | E22: นาย กิตติพงษ์ คงปลอด | F22: 02 ก.พ. 2520 | G22: 47 | H22: Mechanical Technician | I22: Plant Maintenance | J22: Maintenance Repair Overhaul - STS | K22: ชุดคอร์สตรวจสุขภาพ SCG / พนักงาน (ปี67) โปรแกรม 15 (C1E1F1Uหลือง1)
B23: 17 | C23: 6256-66 | D23: =VLOOKUP(C23,[1]รายชื่อ!$C:$D,2,0) -> 0150-021981 | E23: นาย กิตติพงษ์ ดอกไม้ทอง | F23: 27 ก.ค. 2541 | G23: 25 | H23: #N/A | I23: #N/A | J23: #N/A | K23: ชุดคอร์สตรวจสุขภาพ SCG / พนักงาน (ปี67) โปรแกรม 7 (C1E1F1Uเหลือง1U)
B24: 18 | C24: 24617-61 | D24: =VLOOKUP(C24,[1]รายชื่อ!$C:$D,2,0) -> 0150-021167 | E24: นาย กิตติพงษ์ ทองมี | F24: 20 เม.ย. 2535 | G24: 32 | H24: #N/A | I24: #N/A | J24: #N/A | K24: ชุดคอร์สตรวจสุขภาพ SCG / พนักงาน (ปี67) โปรแกรม 15 (C1E1F1Uหลือง1)
B25: 19 | C25: 22368-59 | D25: =VLOOKUP(C25,[1]รายชื่อ!$C:$D,2,0) -> 0150-021191 | E25: นาย กิตติศักดิ์ ช้างกลาง | F25: 14 ก.พ. 2535 | G25: 32 | H25: พนักงานควบคุมจักรกลหนัก | I25: วางแผนและพัฒนาเหมือง | J25: Quarry | K25: ชุดคอร์สตรวจสุขภาพ SCG / พนักงาน (ปี67) โปรแกรม 1 (C1E1F1Uเหลือง1)
B26: 20 | C26: 22377-59 | D26: =VLOOKUP(C26,[1]รายชื่อ!$C:$D,2,0) -> 0150-020783 | E26: นาย กิตติศักดิ์ อ่วมคง | F26: 22 ส.ค. 2531 | G26: 35 | H26: พนักงานควบคุมเครื่องย่อย | I26: ผลิตหินย่อยและหินก่อสร้าง | J26: Quarry | K26: ชุดคอร์สตรวจสุขภาพ SCG / พนักงาน (ปี67) โปรแกรม 7 (C1E1F1Uเหลือง1U)
B27: 21 | C27: 22436-59 | D27: =VLOOKUP(C27,[1]รายชื่อ!$C:$D,2,0) -> 0150-020592 | E27: นาย กิตติ ศิริพันธุ์ | F27: 29 มิ.ย. 2529 | G27: 38 | H27: พนักงานเหมืองแร่ | I27: จัดหาและเตรียมวัตถุดิบ | J27: Quarry | K27: ชุดคอร์สตรวจสุขภาพ SCG / พนักงาน (ปี67) โปรแกรม 1 (C1E1F1Uเหลือง1)
B28: 22 | C28: 4570-62 | D28: =VLOOKUP(C28,[1]รายชื่อ!$C:$D,2,0) -> 0150-020940 | E28: นาย กีรติ ทับทอง | F28: 11 พ.ค. 2531 | G28: 36 | H28: พนักงาน AFR | I28: AFR | J28: Operations | K28: รายการตรวจเพิ่มเติม บ.ปูนซิเมนต์ไทย (ทุ่งสง) / คัดกรองโรคมะเร็ง, ชุดคอร์สตรวจสุขภาพ SCG / พนักงาน (ปี67) โปรแกรม 16 (C1E2F1Uเหลือง1Uแดง4)
B29: 23 | C29: 24218-61 | D29: =VLOOKUP(C29,[1]รายชื่อ!$C:$D,2,0) -> 0150-018430 | E29: นาง กุลธิดา เครือสาย | F29: 27 มิ.ย. 2516 | G29: 51 | H29: พนักงานบริการลูกค้า | I29: บริการลูกค้า | J29: Operations | K29: ชุดตรวจสุขภาพคู่สัญญา ปูน D (อายุ 50 ขึ้นไป หญิง), ชุดคอร์สตรวจสุขภาพ SCG / พนักงาน (ปี67) โปรแกรม 17 (C1F1Uเหลือง1)
B30: 24 | C30: 19923-62 | D30: =VLOOKUP(C30,[1]รายชื่อ!$C:$D,2,0) -> 0150-015842 | E30: นาย เกรียงไกร คุณโลก | F30: 14 ธ.ค. 2513 | G30: 53 | H30: #N/A | I30: #N/A | J30: #N/A | K30: รายการตรวจเพิ่มเติม บ.ปูนซิเมนต์ไทย (ทุ่งสง) / คัดกรองโรคมะเร็ง, ชุดตรวจสุขภาพคู่สัญญา ปูน C (อายุ 50 ขึ้นไป ชาย), ชุดคอร์สตรวจสุขภาพ SCG / พนักงาน (ปี67) โปรแกรม 15 (C1E1F1Uหลือง1)
B31: 25 | C31: 9075-50 | D31: =VLOOKUP(C31,[1]รายชื่อ!$C:$D,2,0) -> 0150-020373 | E31: นาย เกรียงไกร เซ่งเซี่ยง | F31: 25 เม.ย. 2527 | G31: 40 | H31: Mechanical Technician | I31: Plant Maintenance | J31: Maintenance Repair Overhaul - STS | K31: รายการตรวจเพิ่มเติม บ.ปูนซิเมนต์ไทย (ทุ่งสง) / คัดกรองโรคมะเร็ง, ชุดคอร์สตรวจสุขภาพ SCG / พนักงาน (ปี67) โปรแกรม 4 (C1E2F1Uเหลือง1Uแดง3)
B32: 26 | C32: 6253-66 | D32: =VLOOKUP(C32,[1]รายชื่อ!$C:$D,2,0) -> 0150-021969 | E32: นาย เกรียงไกร ธรรมโกศล | F32: 20 ธ.ค. 2536 | G32: 30 | H32: #N/A | I32: #N/A | J32: #N/A | K32: ชุดคอร์สตรวจสุขภาพ SCG / พนักงาน (ปี67) โปรแกรม 7 (C1E1F1Uเหลือง1U)
B33: 27 | C33: 19837-62 | D33: =VLOOKUP(C33,[1]รายชื่อ!$C:$D,2,0) -> 0150-020586 | E33: นาย เกรียงศักดิ์ ชูดวงจันทร์ | F33: 11 มี.ค. 2526 | G33: 41 | H33: #N/A | I33: #N/A | J33: #N/A | K33: ชุดคอร์สตรวจสุขภาพ SCG / พนักงาน (ปี67) โปรแกรม 1 (C1E1F1Uเหลือง1)
B34: 28 | C34: 20003-62 | D34: =VLOOKUP(C34,[1]รายชื่อ!$C:$D,2,0) -> 0150-019534 | E34: นาย เกียรติศักดิ์ ทองทิพย์ | F34: 03 ก.ย. 2516 | G34: 50 | H34: #N/A | I34: #N/A | J34: #N/A | K34: ชุดคอร์สตรวจสุขภาพ SCG / พนักงาน (ปี67) โปรแกรม 15 (C1E1F1Uหลือง1)
B35: 29 | C35: 17784-56 | D35: =VLOOKUP(C35,[1]รายชื่อ!$C:$D,2,0) -> 0150-018799 | E35: นาย เกียรติศักดิ์ ไสยฉิม | F35: 14 ม.ค. 2520 | G35: 47 | H35: พนักงานควบคุมจักรกลหนัก | I35: วางแผนและพัฒนาเหมือง | J35: Quarry | K35: ชุดคอร์สตรวจสุขภาพ SCG / พนักงาน (ปี67) โปรแกรม 1 (C1E1F1Uเหลือง1)
B36: 30 | C36: 24161-61 | D36: =VLOOKUP(C36,[1]รายชื่อ!$C:$D,2,0) -> 0150-021612 | E36: นาย โกมิน บวรศุภศรี | F36: 12 ส.ค. 2537 | G36: 29 | H36: Measurement and Analysis Technician | I36: Measurement and Analysis | J36: Maintenance Repair Overhaul - STS | K36: รายการตรวจเพิ่มเติม สำหรับลูกค้า คู่สัญญา (M) ( ตอบโจทย์ ตรงใจ ), ชุดคอร์สตรวจสุขภาพ SCG / พนักงาน (ปี67) โปรแกรม 8 (C1E1F1Uเหลือง1Uแดง1)
B37: 31 | C37: 7408-51 | D37: =VLOOKUP(C37,[1]รายชื่อ!$C:$D,2,0) -> 0150-014436 | E37: นาย โกสินทร์ ศิริปทาวานิช | F37: 03 ต.ค. 2511 | G37: 55 | H37: ผู้ช่วยผู้จัดการตักและขนส่ง | I37: ผลิตหินก่อนย่อย | J37: Quarry | K37: ชุดคอร์สตรวจสุขภาพ SCG / พนักงาน (ปี67) โปรแกรม 11 (C1F1Uเหลือง1)
B38: 32 | C38: 4362-62 | D38: =VLOOKUP(C38,[1]รายชื่อ!$C:$D,2,0) -> 0150-016714 | E38: นาย ไกรศรี ผาสุข | F38: 27 พ.ค. 2515 | G38: 52 | H38: #N/A | I38: #N/A | J38: #N/A | K38: รายการตรวจเพิ่มเติม สำหรับลูกค้า คู่สัญญา (M) ( ตอบโจทย์ ตรงใจ ), รายการตรวจเพิ่มเติม บ.ปูนซิเมนต์ไทย (ทุ่งสง) / คัดกรองโรคมะเร็ง, ชุดคอร์สตรวจสุขภาพ SCG / พนักงาน (ปี67) โปรแกรม 15 (C1E1F1Uหลือง1)
B39: 33 | C39: 14885-56 | D39: =VLOOKUP(C39,[1]รายชื่อ!$C:$D,2,0) -> 0150-020426 | E39: นาย ไกวัล มวยดี | F39: 02 ก.พ. 2526 | G39: 41 | H39: Measurement and Analysis Technician | I39: Measurement and Analysis | J39: Maintenance Repair Overhaul - STS | K39: ชุดคอร์สตรวจสุขภาพ SCG / พนักงาน (ปี67) โปรแกรม 8 (C1E1F1Uเหลือง1Uแดง1)
B40: 34 | C40: 4216-61 | D40: =VLOOKUP(C40,[1]รายชื่อ!$C:$D,2,0) -> 0150-021423 | E40: นาย ขจรพงศ์ สุวรรณเพ็ชร | F40: 05 เม.ย. 2536 | G40: 31 | H40: พนักงาน Fuel & Export | I40: Fuel and Export | J40: Operations | K40: รายการตรวจเพิ่มเติม สำหรับลูกค้า คู่สัญญา (M) ( ตอบโจทย์ ตรงใจ ), ชุดคอร์สตรวจสุขภาพ SCG / พนักงาน (ปี67) โปรแกรม 15 (C1E1F1Uหลือง1)
B41: 35 | C41: 11762-64 | D41: =VLOOKUP(C41,[1]รายชื่อ!$C:$D,2,0) -> 0150-021944 | E41: น.ส. ขวัญวดี อามิตย์ | F41: 13 พ.ย. 2531 | G41: 35 | H41: #N/A | I41: #N/A | J41: #N/A | K41: ชุดคอร์สตรวจสุขภาพ SCG / พนักงาน (ปี67) โปรแกรม 1 (C1E1F1Uเหลือง1)
B42: 36 | C42: 25972-60 | D42: =VLOOKUP(C42,[1]รายชื่อ!$C:$D,2,0) -> 0150-013365 | E42: นาย คงศักย์ มูลจันทะ | F42: 06 ก.พ. 2510 | G42: 57 | H42: #N/A | I42: #N/A | J42: #N/A | K42: รายการตรวจเพิ่มเติม บ.ปูนซิเมนต์ไทย (ทุ่งสง) / คัดกรองโรคมะเร็ง, ชุดตรวจสุขภาพคู่สัญญา ปูน C (อายุ 50 ขึ้นไป ชาย), ชุดคอร์สตรวจสุขภาพ SCG / พนักงาน (ปี67) โปรแกรม 1 (C1E1F1Uเหลือง1)
B43: 37 | C43: 13651-51 | D43: =VLOOKUP(C43,[1]รายชื่อ!$C:$D,2,0) -> 0150-020475 | E43: นาย คณากร สังข์ทอง | F43: 27 ส.ค. 2530 | G43: 36 | H43: Electrical Technician | I43: Plant Maintenance | J43: Maintenance Repair Overhaul - STS | K43: ชุดคอร์สตรวจสุขภาพ SCG / พนักงาน (ปี67) โปรแกรม 15 (C1E1F1Uหลือง1)
...

Sheet Sheet1
A1: SCG Employee ID | B1: ชื่อ - สกุล | C1: วัน/เดือน/ปีเกิด | D1: อายุ | E1: โปรแกรม
A2: 0150-020685 | B2: นาย ก้าน สิทธิวงศ์ | C2: 28 ก.ค. 2525 | D2: 41 | E2: ชุดตรวจสุขภาพคู่สัญญา ปูน B (อายุ35-50 ปี), รายการตรวจเพิ่มเติม สำหรับลูกค้า คู่สัญญา (M) ( ตอบโจทย์ ตรงใจ ), รายการตรวจเพิ่มเติม บ.ปูนซิเมนต์ไทย (ทุ่งสง) / คัดกรองโรคมะเร็ง, ชุดคอร์สตรวจสุขภาพ SCG / พนักงาน (ปี67) โปรแกรม 8 (C1E1F1Uเหลือง1Uแดง1)
A3: 0150-020460 | B3: นาย กิตติพงศ์ สหกโร | C3: 30 เม.ย. 2530 | D3: 37 | E3: ชุดตรวจสุขภาพคู่สัญญา ปูน B (อายุ35-50 ปี), ชุดคอร์สตรวจสุขภาพ SCG / พนักงาน (ปี67) โปรแกรม 7 (C1E1F1Uเหลือง1U)
A4: 0150-018430 | B4: นาง กุลธิดา เครือสาย | C4: 27 มิ.ย. 2516 | D4: 51 | E4: ชุดตรวจสุขภาพคู่สัญญา ปูน D (อายุ 50 ขึ้นไป หญิง), ชุดคอร์สตรวจสุขภาพ SCG / พนักงาน (ปี67) โปรแกรม 17 (C1F1Uเหลือง1)
A5: 0150-015842 | B5: นาย เกรียงไกร คุณโลก | C5: 14 ธ.ค. 2513 | D5: 53 | E5: รายการตรวจเพิ่มเติม บ.ปูนซิเมนต์ไทย (ทุ่งสง) / คัดกรองโรคมะเร็ง, ชุดตรวจสุขภาพคู่สัญญา ปูน C (อายุ 50 ขึ้นไป ชาย), ชุดคอร์สตรวจสุขภาพ SCG / พนักงาน (ปี67) โปรแกรม 15 (C1E1F1Uหลือง1)
A6: 0150-013365 | B6: นาย คงศักย์ มูลจันทะ | C6: 06 ก.พ. 2510 | D6: 57 | E6: รายการตรวจเพิ่มเติม บ.ปูนซิเมนต์ไทย (ทุ่งสง) / คัดกรองโรคมะเร็ง, ชุดตรวจสุขภาพคู่สัญญา ปูน C (อายุ 50 ขึ้นไป ชาย), ชุดคอร์สตรวจสุขภาพ SCG / พนักงาน (ปี67) โปรแกรม 1 (C1E1F1Uเหลือง1)
A7: 0150-020837 | B7: นาย คำรณ ครองรักษ์ | C7: 27 มิ.ย. 2531 | D7: 36 | E7: รายการตรวจเพิ่มเติม บ.ปูนซิเมนต์ไทย (ทุ่งสง) / คัดกรองโรคมะเร็ง, ชุดตรวจสุขภาพคู่สัญญา ปูน B (อายุ35-50 ปี), ชุดคอร์สตรวจสุขภาพ SCG / พนักงาน (ปี67) โปรแกรม 15 (C1E1F1Uหลือง1)
A8: 0150-019533 | B8: นาย จตุรงค์ เลขาวิจิตร์ | C8: 02 ก.พ. 2520 | D8: 47 | E8: ชุดตรวจสุขภาพคู่สัญญา ปูน B (อายุ35-50 ปี), รายการตรวจเพิ่มเติม บ.ปูนซิเมนต์ไทย (ทุ่งสง) / คัดกรองโรคมะเร็ง, ชุดคอร์สตรวจสุขภาพ SCG / พนักงาน (ปี67) โปรแกรม 15 (C1E1F1Uหลือง1)
A9: 0150-020770 | B9: นาง จุฑารัตน์ คงศิริ | C9: 17 เม.ย. 2532 | D9: 35 | E9: ชุดตรวจสุขภาพคู่สัญญา ปูน B (อายุ35-50 ปี), ชุดคอร์สตรวจสุขภาพ SCG / พนักงาน (ปี67) โปรแกรม 17 (C1F1Uเหลือง1)
A10: 0150-015907 | B10: นาย ฉัตรชัย ตันติพุฒิกุล | C10: 10 ก.ย. 2511 | D10: 55 | E10: ชุดตรวจสุขภาพคู่สัญญา ปูน C (อายุ 50 ขึ้นไป ชาย), ชุดตรวจสุขภาพ สายตาโดยจักษุแพทย์, ชุดคอร์สตรวจสุขภาพ SCG / พนักงาน (ปี67) โปรแกรม 9 (C1F1Uเหลือง1)
A11: 0150-019341 | B11: นาย ชัยภัทร ปิยะเกศกุล | C11: 11 ก.ค. 2519 | D11: 48 | E11: ชุดตรวจสุขภาพคู่สัญญา ปูน B (อายุ35-50 ปี), ชุดคอร์สตรวจสุขภาพ SCG / พนักงาน (ปี67) โปรแกรม 1 (C1E1F1Uเหลือง1)
A12: 0150-020687 | B12: นาย เถลิงเกียรติ สาวีกุลจงรักษ์ | C12: 07 มี.ค. 2530 | D12: 37 | E12: ชุดตรวจสุขภาพคู่สัญญา ปูน B (อายุ35-50 ปี), ชุดคอร์สตรวจสุขภาพ SCG / พนักงาน (ปี67) โปรแกรม 15 (C1E1F1Uหลือง1)
A13: #N/A | B13: นาย ทวีศักดิ์ ศิริบุญประเสริฐ | C13: 24 ม.ค. 2518 | D13: 49 | E13: รายการตรวจเพิ่มเติม บ.ปูนซิเมนต์ไทย (ทุ่งสง) / คัดกรองโรคมะเร็ง, ชุดตรวจสุขภาพคู่สัญญา ปูน B (อายุ35-50 ปี), ชุดคอร์สตรวจสุขภาพ SCG / พนักงาน (ปี67) โปรแกรม 15 (C1E1F1Uหลือง1)
A14: 0150-019506 | B14: นาย ธนิต ว่องไวโรจน์ | C14: 30 มิ.ย. 2519 | D14: 48 | E14: ชุดตรวจสุขภาพคู่สัญญา ปูน B (อายุ35-50 ปี), ชุดคอร์สตรวจสุขภาพ SCG / พนักงาน (ปี67) โปรแกรม 15 (C1E1F1Uหลือง1)
A15: 0150-018567 | B15: นาย ธีระพล บุรีรักษ์ | C15: 12 ต.ค. 2514 | D15: 52 | E15: ชุดตรวจสุขภาพคู่สัญญา ปูน C (อายุ 50 ขึ้นไป ชาย), รายการตรวจเพิ่มเติม บ.ปูนซิเมนต์ไทย (ทุ่งสง) / คัดกรองโรคมะเร็ง, ชุดคอร์สตรวจสุขภาพ SCG / พนักงาน (ปี67) โปรแกรม 15 (C1E1F1Uหลือง1)
A16: 0150-018635 | B16: นาย นุชน้อย รักษ์กำเนิด | C16: 16 ต.ค. 2513 | D16: 53 | E16: รายการตรวจเพิ่มเติม บ.ปูนซิเมนต์ไทย (ทุ่งสง) / คัดกรองโรคมะเร็ง, ชุดตรวจสุขภาพคู่สัญญา ปูน C (อายุ 50 ขึ้นไป ชาย), ชุดคอร์สตรวจสุขภาพ SCG / พนักงาน (ปี67) โปรแกรม 1 (C1E1F1Uเหลือง1)
A17: 0120-022767 | B17: นาย บรรพต เพชรชนะ | C17: 16 พ.ย. 2519 | D17: 47 | E17: รายการตรวจเพิ่มเติม บ.ปูนซิเมนต์ไทย (ทุ่งสง) / คัดกรองโรคมะเร็ง, ชุดตรวจสุขภาพคู่สัญญา ปูน B (อายุ35-50 ปี), ชุดคอร์สตรวจสุขภาพ SCG / พนักงาน (ปี67) โปรแกรม 15 (C1E1F1Uหลือง1)
A18: 0150-017518 | B18: นาย บุรินทร์ อักษรวรรณ | C18: 05 พ.ค. 2514 | D18: 53 | E18: ชุดตรวจสุขภาพคู่สัญญา ปูน C (อายุ 50 ขึ้นไป ชาย), ชุดคอร์สตรวจสุขภาพ SCG / พนักงาน (ปี67) โปรแกรม 1 (C1E1F1Uเหลือง1)
A19: 0150-022094 | B19: นาย ประภาส แก้วพงศ์พันธุ์ | C19: 05 ส.ค. 2512 | D19: 54 | E19: ชุดตรวจสุขภาพคู่สัญญา ปูน C (อายุ 50 ขึ้นไป ชาย), รายการตรวจเพิ่มเติม สำหรับลูกค้า คู่สัญญา (M) ( ตอบโจทย์ ตรงใจ ), รายการตรวจเพิ่มเติม บ.ปูนซิเมนต์ไทย (ทุ่งสง) / คัดกรองโรคมะเร็ง, ชุดคอร์สตรวจสุขภาพ SCG / พนักงาน (ปี67) โปรแกรม 1 (C1E1F1Uเหลือง1)
A20: 0150-020420 | B20: นาย ประสาน ทองสีขำ | C20: 12 ก.ค. 2524 | D20: 43 | E20: รายการตรวจเพิ่มเติม บ.ปูนซิเมนต์ไทย (ทุ่งสง) / คัดกรองโรคมะเร็ง, ชุดตรวจสุขภาพคู่สัญญา ปูน B (อายุ35-50 ปี), ชุดคอร์สตรวจสุขภาพ SCG / พนักงาน (ปี67) โปรแกรม 7 (C1E1F1Uเหลือง1U)
A21: 0150-017516 | B21: นาย ประสิทธิ์ จันทร์ใหม่ | C21: 05 พ.ค. 2516 | D21: 51 | E21: ชุดตรวจสุขภาพคู่สัญญา ปูน C (อายุ 50 ขึ้นไป ชาย), ชุดคอร์สตรวจสุขภาพ SCG / พนักงาน (ปี67) โปรแกรม 1 (C1E1F1Uเหลือง1)
A22: 0150-012525 | B22: นาย ปริญญา ตัณฑชน | C22: 05 ก.ค. 2507 | D22: 60 | E22: ชุดตรวจสุขภาพคู่สัญญา ปูน C (อายุ 50 ขึ้นไป ชาย), ชุดคอร์สตรวจสุขภาพ SCG / พนักงาน (ปี67) โปรแกรม 1 (C1E1F1Uเหลือง1)
A23: 0150-021695 | B23: นาย ปิยพงษ์ ชูชัย | C23: 06 ม.ค. 2528 | D23: 39 | E23: รายการตรวจเพิ่มเติม สำหรับลูกค้า คู่สัญญา (M) ( ตอบโจทย์ ตรงใจ ), ชุดตรวจสุขภาพคู่สัญญา ปูน B (อายุ35-50 ปี), ชุดคอร์สตรวจสุขภาพ SCG / พนักงาน (ปี67) โปรแกรม 17 (C1F1Uเหลือง1)
A24: 0150-020059 | B24: นาย พรรษกร นวลจริง | C24: 10 ก.ย. 2513 | D24: 53 | E24: ชุดตรวจสุขภาพคู่สัญญา ปูน C (อายุ 50 ขึ้นไป ชาย), ชุดคอร์สตรวจสุขภาพ SCG / พนักงาน (ปี67) โปรแกรม 1 (C1E1F1Uเหลือง1)
A25: 0150-021935 | B25: นาย พุทธินันท์ วรรณสวัสดิ์ | C25: 04 พ.ค. 2539 | D25: 28 | E25: รายการตรวจเพิ่มเติม บ.ปูนซิเมนต์ไทย (ทุ่งสง) / คัดกรองโรคมะเร็ง, ชุดตรวจสุขภาพคู่สัญญา ปูน A (อายุน้อยกว่า 35 ปี), ชุดคอร์สตรวจสุขภาพ SCG / พนักงาน (ปี67) โปรแกรม 9 (C1F1Uเหลือง1)
... A42: 0150-018788 | B42: นาย อนุชา แก้วบรรจง | C42: 02 มี.ค. 2518 | D42: 49 | E42: ชุดตรวจสุขภาพคู่สัญญา ปูน B (อายุ35-50 ปี), ชุดคอร์สตรวจสุขภาพ SCG / พนักงาน (ปี67) โปรแกรม 15 (C1E1F1Uหลือง1)

Sheet ความดันโลหิต+ดัชนีมวลกาย
B1: ผลการตรวจความดันโลหิต / ดัชนีมวลกาย (BMI)
B3: ลำดับ | C3: HN | D3: ชื่อ - สกุล | E3: วัน/เดือน/ปีเกิด | F3: อายุ | G3: ตำแหน่งงาน | H3: หน่วยงาน | I3: ส่วน (สำหรับพนักงาน) | J3: น้ำหนัก | K3: ส่วนสูง | L3: ดัชนีมวล กาย | M3: แปลผลดัชนีมวลกาย (BMI) | N3: ความดันโลหิต | Q3: ผลการตรวจ
M4: ค่าปกติ(18.5 - 22.9) | N4: BP Sys | O4: BP Di (60-90) | P4: ชีพจร (60-100 ครั้ง/นาที ) | Q4: ความดันโลหิต | R4: ชีพจร
N5: (90-140)
B6: 1 | C6: 14471-58 | D6: นาง กมลทิพย์ ขบวนสาร | E6: 07 มิ.ย. 2527 | F6: 40 | G6: พนักงานธุรการ | H6: Operations | I6: Operations | J6: 61.3 | K6: 154.2 | L6: 25.78 | M6: อ้วน | N6: 131 | O6: 76 | P6: 79 | Q6: ความดันโลหิตปกติ | R6: ชีพจรปกติ | T6: ดัชนีมวลกาย
B7: 2 | C7: 165-57 | D7: นาย กรณัฐพงษ์ เรืองระพีพรรณ | E7: 04 เม.ย. 2533 | F7: 34 | G7: #N/A | H7: #N/A | I7: #N/A | J7: 71.4 | K7: 174 | L7: 23.58 | M7: น้ำหนักเกินเกณฑ์ | N7: 104 | O7: 62 | P7: 65 | Q7: ความดันโลหิตปกติ | R7: ชีพจรปกติ | T7: ปกติ | U7: 111
B8: 3 | C8: 9043-49 | D8: น.ส. กฤติกา หมัดโส๊ะ | E8: 01 ม.ค. 2528 | F8: 39 | G8: พนักงานเทคโนโลยีสารสนเทศ | H8: เทคโนโลยีสารสนเทศ | I8: MD Office | J8: 52 | K8: 165 | L8: 19.10 | M8: สมส่วน | N8: 106 | O8: 70 | P8: 70 | Q8: ความดันโลหิตปกติ | R8: ชีพจรปกติ | T8: เกินเกณฑ์,อ้วน,อ้วนอันตราย | U8: 355
B9: 4 | C9: 5101-50 | D9: นาย กฤษฎากรณ์ เดชะราช | E9: 18 มิ.ย. 2515 | F9: 52 | G9: Technical and Maintenance Planning Manager | H9: Plant Maintenance | I9: Maintenance Repair Overhaul - STS | J9: 68.5 | K9: 175 | L9: 22.37 | M9: สมส่วน | N9: 106 | O9: 71 | P9: 68 | Q9: ความดันโลหิตปกติ | R9: ชีพจรปกติ | T9: ต่ำ | U9: 5
B10: 5 | C10: 13350-56 | D10: นาย กฤษณรักษ์ รัตนะ | E10: 12 พ.ย. 2530 | F10: 36 | G10: พนักงานซ่อมบำรุงจักรกลหนัก | H10: ซ่อมบำรุงจักรกลหนัก | I10: Quarry | J10: 69.3 | K10: 169 | L10: 24.26 | M10: น้ำหนักเกินเกณฑ์ | N10: 124 | O10: 90 | P10: 83 | Q10: ความดันโลหิตปกติ | R10: ชีพจรปกติ | T10: รวม | U10: 471
B11: 6 | C11: 20669-60 | D11: นาย กฤษดา หนูหอ | E11: 25 เม.ย. 2520 | F11: 47 | G11: Maintenance Overhaul and Consultancy Technician - Electrical | H11: Maintenance Overhaul and Consultancy - Electrical | I11: Maintenance Repair Overhaul - STS | J11: 62.2 | K11: 157.5 | L11: 25.07 | M11: อ้วน | N11: 132 | O11: 90 | P11: 72 | Q11: ความดันโลหิตปกติ | R11: ชีพจรปกติ
B12: 7 | C12: 20050-65 | D12: นาย กวิศ แซ่ตั้ง | E12: 01 ม.ค. 2535 | F12: 32 | G12: #N/A | H12: #N/A | I12: #N/A | J12: 102.1 | K12: 185 | L12: 29.83 | M12: อ้วน | N12: 127 | O12: 79 | P12: 73 | Q12: ความดันโลหิตปกติ | R12: ชีพจรปกติ | T12: ความดันโลหิต
B13: 8 | C13: 11980-47 | D13: นาย ก้องทัย คุณโลก | E13: 17 มี.ค. 2512 | F13: 55 | G13: Mechanical Maintenance Manager – Clinker | H13: Plant Maintenance | I13: Maintenance Repair Overhaul - STS | J13: 76 | K13: 169 | L13: 26.61 | M13: อ้วน | N13: 137 | O13: 91 | P13: 74 | Q13: ความดันโลหิตสูง | R13: ชีพจรปกติ | T13: ปกติ | U13: 404
B14: 9 | C14: 443-50 | D14: นาย กัญจน์ภัสสรณ์ พรหมแสง | E14: 05 มิ.ย. 2519 | F14: 48 | G14: #N/A | H14: #N/A | I14: #N/A | J14: 76.9 | K14: 165 | L14: 28.25 | M14: อ้วน | N14: 139 | O14: 85 | P14: 78 | Q14: ความดันโลหิตปกติ | R14: ชีพจรปกติ | T14: สูงกว่าปกติ | U14: 63
B15: 10 | C15: 19597-49 | D15: น.ส. กัญธนัช ศรีโยธา | E15: 14 ต.ค. 2528 | F15: 38 | G15: BSE Assistant Manager-South Chain | H15: BSE South Chain | I15: BSE South Chain | J15: 61.5 | K15: 162.5 | L15: 23.29 | M15: น้ำหนักเกินเกณฑ์ | N15: 101 | O15: 60 | P15: 71 | Q15: ความดันโลหิตปกติ | R15: ชีพจรปกติ | T15: ต่ำ | U15: 4
B16: 11 | C16: 24355-61 | D16: นาง กาญจนา ลีลารุจนกุล | E16: 13 ต.ค. 2535 | F16: 31 | G16: BSE Operation Officer-STS | H16: BSE Operation - STS | I16: BSE Operation - STS | J16: 56.2 | K16: 163 | L16: 21.15 | M16: สมส่วน | N16: 115 | O16: 81 | P16: 92 | Q16: ความดันโลหิตปกติ | R16: ชีพจรปกติ | T16: รวม | U16: 471
B17: 12 | C17: 11655-54 | D17: นาย ก้าน สิทธิวงศ์ | E17: 28 ก.ค. 2525 | F17: 41 | G17: พนักงานผลิตถุงกระดาษ | H17: ผลิตถุงกระดาษ | I17: Operations | J17: 86 | K17: 168 | L17: 30.47 | M17: อ้วนอันตราย | N17: 133 | O17: 82 | P17: 76 | Q17: ความดันโลหิตปกติ | R17: ชีพจรปกติ
B18: 13 | C18: 4482-62 | D18: นาย กิตตินันท์ จันทกูล | E18: 27 ก.ย. 2534 | F18: 32 | G18: Mechanical Technician | H18: Plant Maintenance | I18: Maintenance Repair Overhaul - STS | J18: 79.1 | K18: 166 | L18: 28.71 | M18: อ้วน | N18: 114 | O18: 69 | P18: 60 | Q18: ความดันโลหิตปกติ | R18: ชีพจรปกติ
B19: 14 | C19: 16852-60 | D19: นาย กิตติพงศ์ ไพชำนาญ | E19: 04 มี.ค. 2535 | F19: 32 | G19: Engineer | H19: Maintenance Repair Overhaul - STS | I19: Maintenance Repair Overhaul - STS | J19: 63 | K19: 167 | L19: 22.59 | M19: สมส่วน | N19: 116 | O19: 62 | P19: 76 | Q19: ความดันโลหิตปกติ | R19: ชีพจรปกติ
B20: 15 | C20: 22376-59 | D20: นาย กิตติพงศ์ สหกโร | E20: 30 เม.ย. 2530 | F20: 37 | G20: พนักงานควบคุมเครื่องย่อย | H20: ผลิตหินย่อยและหินก่อสร้าง | I20: Quarry | J20: 89 | K20: 173 | L20: 29.74 | M20: อ้วน | N20: 116 | O20: 75 | P20: 65 | Q20: ความดันโลหิตปกติ | R20: ชีพจรปกติ
B21: 16 | C21: 3969-43 | D21: นาย กิตติพงษ์ คงปลอด | E21: 02 ก.พ. 2520 | F21: 47 | G21: Mechanical Technician | H21: Plant Maintenance | I21: Maintenance Repair Overhaul - STS | J21: 65 | K21: 167 | L21: 23.31 | M21: น้ำหนักเกินเกณฑ์ | N21: 110 | O21: 72 | P21: 78 | Q21: ความดันโลหิตปกติ | R21: ชีพจรปกติ
B22: 17 | C22: 6256-66 | D22: นาย กิตติพงษ์ ดอกไม้ทอง | E22: 27 ก.ค. 2541 | F22: 25 | G22: #N/A | H22: #N/A | I22: #N/A | J22: 66.9 | K22: 161 | L22: 25.81 | M22: อ้วน | N22: 105 | O22: 60 | P22: 82 | Q22: ความดันโลหิตปกติ | R22: ชีพจรปกติ
B23: 18 | C23: 24617-61 | D23: นาย กิตติพงษ์ ทองมี | E23: 20 เม.ย. 2535 | F23: 32 | G23: #N/A | H23: #N/A | I23: #N/A | J23: 62.5 | K23: 167 | L23: 22.41 | M23: สมส่วน | N23: 123 | O23: 69 | P23: 69 | Q23: ความดันโลหิตปกติ | R23: ชีพจรปกติ
B24: 19 | C24: 22368-59 | D24: นาย กิตติศักดิ์ ช้างกลาง | E24: 14 ก.พ. 2535 | F24: 32 | G24: พนักงานควบคุมจักรกลหนัก | H24: วางแผนและพัฒนาเหมือง | I24: Quarry | J24: 70.7 | K24: 169 | L24: 24.75 | M24: น้ำหนักเกินเกณฑ์ | N24: 114 | O24: 81 | P24: 67 | Q24: ความดันโลหิตปกติ | R24: ชีพจรปกติ
B25: 20 | C25: 22377-59 | D25: นาย กิตติศักดิ์ อ่วมคง | E25: 22 ส.ค. 2531 | F25: 35 | G25: พนักงานควบคุมเครื่องย่อย | H25: ผลิตหินย่อยและหินก่อสร้าง | I25: Quarry | J25: 69 | K25: 163 | L25: 25.97 | M25: อ้วน | N25: 108 | O25: 70 | P25: 72 | Q25: ความดันโลหิตปกติ | R25: ชีพจรปกติ
B26: 21 | C26: 22436-59 | D26: นาย กิตติ ศิริพันธุ์ | E26: 29 มิ.ย. 2529 | F26: 38 | G26: พนักงานเหมืองแร่ | H26: จัดหาและเตรียมวัตถุดิบ | I26: Quarry | J26: 87.4 | K26: 172 | L26: 29.54 | M26: อ้วน | N26: 130 | O26: 85 | P26: 61 | Q26: ความดันโลหิตปกติ | R26: ชีพจรปกติ
B27: 22 | C27: 4570-62 | D27: นาย กีรติ ทับทอง | E27: 11 พ.ค. 2531 | F27: 36 | G27: พนักงาน AFR | H27: AFR | I27: Operations | J27: 51.6 | K27: 171 | L27: 17.65 | M27: น้ำหนักต่ำกว่าเกณฑ์ | N27: 108 | O27: 77 | P27: 79 | Q27: ความดันโลหิตปกติ | R27: ชีพจรปกติ
B28: 23 | C28: 24218-61 | D28: นาง กุลธิดา เครือสาย | E28: 27 มิ.ย. 2516 | F28: 51 | G28: พนักงานบริการลูกค้า | H28: บริการลูกค้า | I28: Operations | J28: 73.8 | K28: 155 | L28: 30.72 | M28: อ้วนอันตราย | N28: 137 | O28: 72 | P28: 60 | Q28: ความดันโลหิตปกติ | R28: ชีพจรปกติ
B29: 24 | C29: 19923-62 | D29: นาย เกรียงไกร คุณโลก | E29: 14 ธ.ค. 2513 | F29: 53 | G29: #N/A | H29: #N/A | I29: #N/A | J29: 66.6 | K29: 158 | L29: 26.68 | M29: อ้วน | N29: 151 | O29: 90 | P29: 70 | Q29: ความดันโลหิตสูง | R29: ชีพจรปกติ
B30: 25 | C30: 9075-50 | D30: นาย เกรียงไกร เซ่งเซี่ยง | E30: 25 เม.ย. 2527 | F30: 40 | G30: Mechanical Technician | H30: Plant Maintenance | I30: Maintenance Repair Overhaul - STS | J30: 58.9 | K30: 161 | L30: 22.72 | M30: สมส่วน | N30: 128 | O30: 78 | P30: 60 | Q30: ความดันโลหิตปกติ | R30: ชีพจรปกติ
B31: 26 | C31: 6253-66 | D31: นาย เกรียงไกร ธรรมโกศล | E31: 20 ธ.ค. 2536 | F31: 30 | G31: #N/A | H31: #N/A | I31: #N/A | J31: 65.7 | K31: 165.5 | L31: 23.99 | M31: น้ำหนักเกินเกณฑ์ | N31: 110 | O31: 68 | P31: 60 | Q31: ความดันโลหิตปกติ | R31: ชีพจรปกติ
B32: 27 | C32: 19837-62 | D32: นาย เกรียงศักดิ์ ชูดวงจันทร์ | E32: 11 มี.ค. 2526 | F32: 41 | G32: #N/A | H32: #N/A | I32: #N/A | J32: 57.7 | K32: 171 | L32: 19.73 | M32: สมส่วน | N32: 104 | O32: 67 | P32: 82 | Q32: ความดันโลหิตปกติ | R32: ชีพจรปกติ
B33: 28 | C33: 20003-62 | D33: นาย เกียรติศักดิ์ ทองทิพย์ | E33: 03 ก.ย. 2516 | F33: 50 | G33: #N/A | H33: #N/A | I33: #N/A | J33: 62.8 | K33: 170.5 | L33: 21.60 | M33: สมส่วน | N33: 118 | O33: 73 | P33: 76 | Q33: ความดันโลหิตปกติ | R33: ชีพจรปกติ
B34: 29 | C34: 17784-56 | D34: นาย เกียรติศักดิ์ ไสยฉิม | E34: 14 ม.ค. 2520 | F34: 47 | G34: พนักงานควบคุมจักรกลหนัก | H34: วางแผนและพัฒนาเหมือง | I34: Quarry | J34: 80.7 | K34: 175 | L34: 26.35 | M34: อ้วน | N34: 133 | O34: 82 | P34: 73 | Q34: ความดันโลหิตปกติ | R34: ชีพจรปกติ
B35: 30 | C35: 24161-61 | D35: นาย โกมิน บวรศุภศรี | E35: 12 ส.ค. 2537 | F35: 29 | G35: Measurement and Analysis Technician | H35: Measurement and Analysis | I35: Maintenance Repair Overhaul - STS | J35: 86 | K35: 167 | L35: 30.84 | M35: อ้วนอันตราย | N35: 134 | O35: 75 | P35: 61 | Q35: ความดันโลหิตปกติ | R35: ชีพจรปกติ
B36: 31 | C36: 7408-51 | D36: นาย โกสินทร์ ศิริปทาวานิช | E36: 03 ต.ค. 2511 | F36: 55 | G36: ผู้ช่วยผู้จัดการตักและขนส่ง | H36: ผลิตหินก่อนย่อย | I36: Quarry | J36: 69.1 | K36: 169 | L36: 24.19 | M36: น้ำหนักเกินเกณฑ์ | N36: 135 | O36: 90 | P36: 80 | Q36: ความดันโลหิตปกติ | R36: ชีพจรปกติ
B37: 32 | C37: 4362-62 | D37: นาย ไกรศรี ผาสุข | E37: 27 พ.ค. 2515 | F37: 52 | G37: #N/A | H37: #N/A | I37: #N/A | J37: 62.4 | K37: 168 | L37: 22.11 | M37: สมส่วน | N37: 102 | O37: 76 | P37: 82 | Q37: ความดันโลหิตปกติ | R37: ชีพจรปกติ
B38: 33 | C38: 14885-56 | D38: นาย ไกวัล มวยดี | E38: 02 ก.พ. 2526 | F38: 41 | G38: Measurement and Analysis Technician | H38: Measurement and Analysis | I38: Maintenance Repair Overhaul - STS | J38: 81.3 | K38: 175 | L38: 26.55 | M38: อ้วน | N38: 140 | O38: 100 | P38: 86 | Q38: ความดันโลหิตสูง | R38: ชีพจรปกติ
B39: 34 | C39: 4216-61 | D39: นาย ขจรพงศ์ สุวรรณเพ็ชร | E39: 05 เม.ย. 2536 | F39: 31 | G39: พนักงาน Fuel & Export | H39: Fuel and Export | I39: Operations | J39: 93.5 | K39: 164 | L39: 34.76 | M39: อ้วนอันตราย | N39: 139 | O39: 78 | P39: 78 | Q39: ความดันโลหิตปกติ | R39: ชีพจรปกติ
B40: 35 | C40: 11762-64 | D40: น.ส. ขวัญวดี อามิตย์ | E40: 13 พ.ย. 2531 | F40: 35 | G40: #N/A | H40: #N/A | I40: #N/A | J40: 90.2 | K40: 166.3 | L40: 32.62 | M40: อ้วนอันตราย | N40: 109 | O40: 62 | P40: 67 | Q40: ความดันโลหิตปกติ | R40: ชีพจรปกติ
B41: 36 | C41: 25972-60 | D41: นาย คงศักย์ มูลจันทะ | E41: 06 ก.พ. 2510 | F41: 57 | G41: #N/A | H41: #N/A | I41: #N/A | J41: 84.6 | K41: 165 | L41: 31.07 | M41: อ้วนอันตราย | N41: 151 | O41: 98 | P41: 70 | Q41: ความดันโลหิตสูง | R41: ชีพจรปกติ
...

Sheet ไขมัน+น้ำตาลในเลือด
B1: ผลการตรวจไขมันและน้ำตาลในเลือด (Lipid Profile , FBS)
B3: No | C3: HN | D3: ชื่อ - สกุล | E3: วัน/เดือน/ปีเกิด | F3: อายุ | G3: ตำแหน่งงาน | H3: หน่วยงาน | I3: ส่วน (สำหรับพนักงาน) | J3: ไขมัน | K3: ไขมันไตรกลีเซอไรด์ | L3: ไขมันชนิดดีในเลือด (HDL) | M3: ไขมันร้าย (LDL) | N3: สรุปผลการตรวจไขมันในเลือด | O3: น้ำตาลในเลือด (FBS) | P3: สรุปผลการตรวจน้ำตาลในเลือด
J4: คลอเลสเตอรอล | K4: (Triglyceride)
J5: (Cholesterol)
P6: ค่าปกติ 70-99
J7: ค่าปกติ (<200) | K7: ค่าปกติ (<150) | L7: ค่าปกติ ญ(>50) | M7: ค่าปกติ (<130)
L8: ช(>40)
B9: 1 | C9: 14471-58 | D9: นาง กมลทิพย์ ขบวนสาร | E9: 07 มิ.ย. 2527 | F9: 40 | G9: พนักงานธุรการ | H9: Operations | I9: Operations | J9: 238 | K9: 110 | L9: 68 | M9: 149 | N9: ไขมันในเลือดสูง | O9: 90 | P9: ระดับน้ำตาลในเลือดปกติ | R9: ไขมันในเลือด
B10: 2 | C10: 165-57 | D10: นาย กรณัฐพงษ์ เรืองระพีพรรณ | E10: 04 เม.ย. 2533 | F10: 34 | G10: #N/A | H10: #N/A | I10: #N/A | J10: 233 | K10: 129 | L10: 52 | M10: 155 | N10: ไขมันในเลือดสูง | O10: 83 | P10: ระดับน้ำตาลในเลือดปกติ | R10: ปกติ | S10: 87
B11: 3 | C11: 9043-49 | D11: น.ส. กฤติกา หมัดโส๊ะ | E11: 01 ม.ค. 2528 | F11: 39 | G11: พนักงานเทคโนโลยีสารสนเทศ | H11: เทคโนโลยีสารสนเทศ | I11: MD Office | J11: 238 | K11: 79 | L11: 51 | M11: 171 | N11: ไขมันในเลือดสูง | O11: 79 | P11: ระดับน้ำตาลในเลือดปกติ | R11: ผิดปกติ | S11: 363
B12: 4 | C12: 5101-50 | D12: นาย กฤษฎากรณ์ เดชะราช | E12: 18 มิ.ย. 2515 | F12: 52 | G12: Technical and Maintenance Planning Manager | H12: Plant Maintenance | I12: Maintenance Repair Overhaul - STS | J12: - | K12: - | L12: - | M12: - | N12: ไม่ได้รับการตรวจ | O12: - | P12: ไม่ได้รับการตรวจ | R12: รวม | S12: 450
B13: 5 | C13: 13350-56 | D13: นาย กฤษณรักษ์ รัตนะ | E13: 12 พ.ย. 2530 | F13: 36 | G13: พนักงานซ่อมบำรุงจักรกลหนัก | H13: ซ่อมบำรุงจักรกลหนัก | I13: Quarry | J13: 214 | K13: 196 | L13: 70 | M13: 105 | N13: ไขมันในเลือดสูง | O13: 94 | P13: ระดับน้ำตาลในเลือดปกติ
B14: 6 | C14: 20669-60 | D14: นาย กฤษดา หนูหอ | E14: 25 เม.ย. 2520 | F14: 47 | G14: Maintenance Overhaul and Consultancy Technician - Electrical | H14: Maintenance Overhaul and Consultancy - Electrical | I14: Maintenance Repair Overhaul - STS | J14: 210 | K14: 79 | L14: 107 | M14: 88 | N14: ไขมันคลอเลสเตอรอลสูง | O14: 83 | P14: ระดับน้ำตาลในเลือดปกติ | R14: น้ำตาลในเลือด
B15: 7 | C15: 20050-65 | D15: นาย กวิศ แซ่ตั้ง | E15: 01 ม.ค. 2535 | F15: 32 | G15: #N/A | H15: #N/A | I15: #N/A | J15: 230 | K15: 148 | L15: 61 | M15: 139 | N15: ไขมันในเลือดสูง | O15: 86 | P15: ระดับน้ำตาลในเลือดปกติ | R15: ปกติ | S15: 370
B16: 8 | C16: 11980-47 | D16: นาย ก้องทัย คุณโลก | E16: 17 มี.ค. 2512 | F16: 55 | G16: Mechanical Maintenance Manager – Clinker | H16: Plant Maintenance | I16: Maintenance Repair Overhaul - STS | J16: 217 | K16: 170 | L16: 47 | M16: 137 | N16: ไขมันในเลือดสูง | O16: 88 | P16: ระดับน้ำตาลในเลือดปกติ | R16: ผิดปกติ | S16: 79
B17: 9 | C17: 443-50 | D17: นาย กัญจน์ภัสสรณ์ พรหมแสง | E17: 05 มิ.ย. 2519 | F17: 48 | G17: #N/A | H17: #N/A | I17: #N/A | J17: 247 | K17: 250 | L17: 43 | M17: 153 | N17: ไขมันในเลือดสูง | O17: 90 | P17: ระดับน้ำตาลในเลือดปกติ | R17: รวม | S17: 449
B18: 10 | C18: 19597-49 | D18: น.ส. กัญธนัช ศรีโยธา | E18: 14 ต.ค. 2528 | F18: 38 | G18: BSE Assistant Manager-South Chain | H18: BSE South Chain | I18: BSE South Chain | J18: 248 | K18: 94 | L18: 58 | M18: 172 | N18: ไขมันในเลือดสูง | O18: 79 | P18: ระดับน้ำตาลในเลือดปกติ
B19: 11 | C19: 24355-61 | D19: นาง กาญจนา ลีลารุจนกุล | E19: 13 ต.ค. 2535 | F19: 31 | G19: BSE Operation Officer-STS | H19: BSE Operation - STS | I19: BSE Operation - STS | J19: 164 | K19: 57 | L19: 70 | M19: 82 | N19: ปกติ | O19: 81 | P19: ระดับน้ำตาลในเลือดปกติ
B20: 12 | C20: 11655-54 | D20: นาย ก้าน สิทธิวงศ์ | E20: 28 ก.ค. 2525 | F20: 41 | G20: พนักงานผลิตถุงกระดาษ | H20: ผลิตถุงกระดาษ | I20: Operations | J20: 243 | K20: 264 | L20: 42 | M20: 147 | N20: ไขมันในเลือดสูง | O20: 95 | P20: ระดับน้ำตาลในเลือดปกติ
B21: 13 | C21: 4482-62 | D21: นาย กิตตินันท์ จันทกูล | E21: 27 ก.ย. 2534 | F21: 32 | G21: Mechanical Technician | H21: Plant Maintenance | I21: Maintenance Repair Overhaul - STS | J21: 269 | K21: 125 | L21: 47 | M21: 197 | N21: ไขมันในเลือดสูง | O21: 98 | P21: ระดับน้ำตาลในเลือดปกติ
B22: 14 | C22: 16852-60 | D22: นาย กิตติพงศ์ ไพชำนาญ | E22: 04 มี.ค. 2535 | F22: 32 | G22: Engineer | H22: Maintenance Repair Overhaul - STS | I22: Maintenance Repair Overhaul - STS | J22: 278 | K22: 125 | L22: 46 | M22: 207 | N22: ไขมันในเลือดสูง | O22: 90 | P22: ระดับน้ำตาลในเลือดปกติ
B23: 15 | C23: 22376-59 | D23: นาย กิตติพงศ์ สหกโร | E23: 30 เม.ย. 2530 | F23: 37 | G23: พนักงานควบคุมเครื่องย่อย | H23: ผลิตหินย่อยและหินก่อสร้าง | I23: Quarry | J23: 212 | K23: 117 | L23: 53 | M23: 135 | N23: ไขมันในเลือดสูง | O23: 113 | P23: ระดับน้ำตาลในเลือดสูงกว่าปกติ
B24: 16 | C24: 3969-43 | D24: นาย กิตติพงษ์ คงปลอด | E24: 02 ก.พ. 2520 | F24: 47 | G24: Mechanical Technician | H24: Plant Maintenance | I24: Maintenance Repair Overhaul - STS | J24: 213 | K24: 302 | L24: 41 | M24: 111 | N24: ไขมันในเลือดสูง | O24: 118 | P24: ระดับน้ำตาลในเลือดสูงกว่าปกติ
B25: 17 | C25: 6256-66 | D25: นาย กิตติพงษ์ ดอกไม้ทอง | E25: 27 ก.ค. 2541 | F25: 25 | G25: #N/A | H25: #N/A | I25: #N/A | J25: 378 | K25: 286 | L25: 45 | M25: 276 | N25: ไขมันในเลือดสูง | O25: 82 | P25: ระดับน้ำตาลในเลือดปกติ
B26: 18 | C26: 24617-61 | D26: นาย กิตติพงษ์ ทองมี | E26: 20 เม.ย. 2535 | F26: 32 | G26: #N/A | H26: #N/A | I26: #N/A | J26: 116 | K26: 81 | L26: 62 | M26: 38 | N26: ปกติ | O26: 81 | P26: ระดับน้ำตาลในเลือดปกติ
B27: 19 | C27: 22368-59 | D27: นาย กิตติศักดิ์ ช้างกลาง | E27: 14 ก.พ. 2535 | F27: 32 | G27: พนักงานควบคุมจักรกลหนัก | H27: วางแผนและพัฒนาเหมือง | I27: Quarry | J27: 170 | K27: 71 | L27: 57 | M27: 98 | N27: ปกติ | O27: 75 | P27: ระดับน้ำตาลในเลือดปกติ
B28: 20 | C28: 22377-59 | D28: นาย กิตติศักดิ์ อ่วมคง | E28: 22 ส.ค. 2531 | F28: 35 | G28: พนักงานควบคุมเครื่องย่อย | H28: ผลิตหินย่อยและหินก่อสร้าง | I28: Quarry | J28: 248 | K28: 402 | L28: 39 | M28: 128 | N28: ไขมันในเลือดสูง ไขมันดี (HDL) ต่ำ | O28: 86 | P28: ระดับน้ำตาลในเลือดปกติ
B29: 21 | C29: 22436-59 | D29: นาย กิตติ ศิริพันธุ์ | E29: 29 มิ.ย. 2529 | F29: 38 | G29: พนักงานเหมืองแร่ | H29: จัดหาและเตรียมวัตถุดิบ | I29: Quarry | J29: 254 | K29: 479 | L29: 36 | M29: 143 | N29: ไขมันในเลือดสูง ไขมันดี (HDL) ต่ำ | O29: 94 | P29: ระดับน้ำตาลในเลือดปกติ
B30: 22 | C30: 4570-62 | D30: นาย กีรติ ทับทอง | E30: 11 พ.ค. 2531 | F30: 36 | G30: พนักงาน AFR | H30: AFR | I30: Operations | J30: 167 | K30: 91 | L30: 58 | M30: 90 | N30: ปกติ | O30: 85 | P30: ระดับน้ำตาลในเลือดปกติ
B31: 23 | C31: 24218-61 | D31: นาง กุลธิดา เครือสาย | E31: 27 มิ.ย. 2516 | F31: 51 | G31: พนักงานบริการลูกค้า | H31: บริการลูกค้า | I31: Operations | J31: 264 | K31: 103 | L31: 52 | M31: 192 | N31: ไขมันในเลือดสูง | O31: 115 | P31: ระดับน้ำตาลในเลือดสูงกว่าปกติ
B32: 24 | C32: 19923-62 | D32: นาย เกรียงไกร คุณโลก | E32: 14 ธ.ค. 2513 | F32: 53 | G32: #N/A | H32: #N/A | I32: #N/A | J32: 172 | K32: 98 | L32: 64 | M32: 88 | N32: ปกติ | O32: 97 | P32: ระดับน้ำตาลในเลือดปกติ
B33: 25 | C33: 9075-50 | D33: นาย เกรียงไกร เซ่งเซี่ยง | E33: 25 เม.ย. 2527 | F33: 40 | G33: Mechanical Technician | H33: Plant Maintenance | I33: Maintenance Repair Overhaul - STS | J33: 207 | K33: 112 | L33: 65 | M33: 120 | N33: ไขมันคลอเลสเตอรอลสูง | O33: 86 | P33: ระดับน้ำตาลในเลือดปกติ
B34: 26 | C34: 6253-66 | D34: นาย เกรียงไกร ธรรมโกศล | E34: 20 ธ.ค. 2536 | F34: 30 | G34: #N/A | H34: #N/A | I34: #N/A | J34: 177 | K34: 59 | L34: 54 | M34: 111 | N34: ปกติ | O34: 84 | P34: ระดับน้ำตาลในเลือดปกติ
B35: 27 | C35: 19837-62 | D35: นาย เกรียงศักดิ์ ชูดวงจันทร์ | E35: 11 มี.ค. 2526 | F35: 41 | G35: #N/A | H35: #N/A | I35: #N/A | J35: 164 | K35: 68 | L35: 44 | M35: 107 | N35: ปกติ | O35: 95 | P35: ระดับน้ำตาลในเลือดปกติ
B36: 28 | C36: 20003-62 | D36: นาย เกียรติศักดิ์ ทองทิพย์ | E36: 03 ก.ย. 2516 | F36: 50 | G36: #N/A | H36: #N/A | I36: #N/A | J36: 190 | K36: 76 | L36: 62 | M36: 113 | N36: ปกติ | O36: 90 | P36: ระดับน้ำตาลในเลือดปกติ
B37: 29 | C37: 17784-56 | D37: นาย เกียรติศักดิ์ ไสยฉิม | E37: 14 ม.ค. 2520 | F37: 47 | G37: พนักงานควบคุมจักรกลหนัก | H37: วางแผนและพัฒนาเหมือง | I37: Quarry | J37: - | K37: - | L37: - | M37: - | N37: ไม่ได้รับการตรวจ | O37: - | P37: ไม่ได้รับการตรวจ
B38: 30 | C38: 24161-61 | D38: นาย โกมิน บวรศุภศรี | E38: 12 ส.ค. 2537 | F38: 29 | G38: Measurement and Analysis Technician | H38: Measurement and Analysis | I38: Maintenance Repair Overhaul - STS | J38: 174 | K38: 78 | L38: 49 | M38: 109 | N38: ปกติ | O38: 84 | P38: ระดับน้ำตาลในเลือดปกติ
B39: 31 | C39: 7408-51 | D39: นาย โกสินทร์ ศิริปทาวานิช | E39: 03 ต.ค. 2511 | F39: 55 | G39: ผู้ช่วยผู้จัดการตักและขนส่ง | H39: ผลิตหินก่อนย่อย | I39: Quarry | J39: 199 | K39: 85 | L39: 56 | M39: 127 | N39: ปกติ | O39: 95 | P39: ระดับน้ำตาลในเลือดปกติ
B40: 32 | C40: 4362-62 | D40: นาย ไกรศรี ผาสุข | E40: 27 พ.ค. 2515 | F40: 52 | G40: #N/A | H40: #N/A | I40: #N/A | J40: 256 | K40: 142 | L40: 56 | M40: 172 | N40: ไขมันในเลือดสูง | O40: 283 | P40: ระดับน้ำตาลในเลือดสูงกว่าปกติ
B41: 33 | C41: 14885-56 | D41: นาย ไกวัล มวยดี | E41: 02 ก.พ. 2526 | F41: 41 | G41: Measurement and Analysis Technician | H41: Measurement and Analysis | I41: Maintenance Repair Overhaul - STS | J41: 215 | K41: 157 | L41: 46 | M41: 137 | N41: ไขมันในเลือดสูง | O41: 93 | P41: ระดับน้ำตาลในเลือดปกติ
...

Sheet การทำงานของตับ
B1: ผลการตรวจเอนไซม์ตับ เพื่อดูภาวะตับอักเสบ (SGPT,SGOT)
B3: No | C3: HN | D3: ชื่อ - สกุล | E3: วัน/เดือน/ปีเกิด | F3: อายุ | G3: ตำแหน่งงาน | H3: หน่วยงาน | I3: ส่วน (สำหรับพนักงาน) | J3: การทำงานของตับ (SGOT) | K3: การทำงานของตับ (SGPT) | L3: การทำงานของตับ (ALKP) | M3: สรุปผลการตรวจ
J5: ช ค่าปกติ 15-46 , ญ ค่าปกติ 15-46 | K5: ช ค่าปกติ <50 , ญ ค่าปกติ <35 | L5: ค่าปกติ 38-126
B6: 1 | C6: 14471-58 | D6: นาง กมลทิพย์ ขบวนสาร | E6: 07 มิ.ย. 2527 | F6: 40 | G6: พนักงานธุรการ | H6: Operations | I6: Operations | J6: - | K6: - | L6: - | M6: ไม่ได้รับการตรวจ | O6: การทำงานของตับ
B7: 2 | C7: 165-57 | D7: นาย กรณัฐพงษ์ เรืองระพีพรรณ | E7: 04 เม.ย. 2533 | F7: 34 | G7: #N/A | H7: #N/A | I7: #N/A | J7: 24 | K7: 32 | L7: 76 | M7: ปกติ | O7: ปกติ | P7: 327
B8: 3 | C8: 9043-49 | D8: น.ส. กฤติกา หมัดโส๊ะ | E8: 01 ม.ค. 2528 | F8: 39 | G8: พนักงานเทคโนโลยีสารสนเทศ | H8: เทคโนโลยีสารสนเทศ | I8: MD Office | J8: - | K8: - | L8: - | M8: ไม่ได้รับการตรวจ | O8: ผิดปกติ | P8: 92
B9: 4 | C9: 5101-50 | D9: นาย กฤษฎากรณ์ เดชะราช | E9: 18 มิ.ย. 2515 | F9: 52 | G9: Technical and Maintenance Planning Manager | H9: Plant Maintenance | I9: Maintenance Repair Overhaul - STS | J9: - | K9: - | L9: - | M9: ไม่ได้รับการตรวจ | O9: รวม | P9: 419
B10: 5 | C10: 13350-56 | D10: นาย กฤษณรักษ์ รัตนะ | E10: 12 พ.ย. 2530 | F10: 36 | G10: พนักงานซ่อมบำรุงจักรกลหนัก | H10: ซ่อมบำรุงจักรกลหนัก | I10: Quarry | J10: 45 | K10: 73 | L10: 72 | M10: ผิดปกติ
B11: 6 | C11: 20669-60 | D11: นาย กฤษดา หนูหอ | E11: 25 เม.ย. 2520 | F11: 47 | G11: Maintenance Overhaul and Consultancy Technician - Electrical | H11: Maintenance Overhaul and Consultancy - Electrical | I11: Maintenance Repair Overhaul - STS | J11: 37 | K11: 23 | L11: 102 | M11: ปกติ
B12: 7 | C12: 20050-65 | D12: นาย กวิศ แซ่ตั้ง | E12: 01 ม.ค. 2535 | F12: 32 | G12: #N/A | H12: #N/A | I12: #N/A | J12: 26 | K12: 35 | L12: 60 | M12: ปกติ
B13: 8 | C13: 11980-47 | D13: นาย ก้องทัย คุณโลก | E13: 17 มี.ค. 2512 | F13: 55 | G13: Mechanical Maintenance Manager – Clinker | H13: Plant Maintenance | I13: Maintenance Repair Overhaul - STS | J13: 36 | K13: 61 | L13: 67 | M13: ผิดปกติ
B14: 9 | C14: 443-50 | D14: นาย กัญจน์ภัสสรณ์ พรหมแสง | E14: 05 มิ.ย. 2519 | F14: 48 | G14: #N/A | H14: #N/A | I14: #N/A | J14: 30 | K14: 40 | L14: 45 | M14: ปกติ
B15: 10 | C15: 19597-49 | D15: น.ส. กัญธนัช ศรีโยธา | E15: 14 ต.ค. 2528 | F15: 38 | G15: BSE Assistant Manager-South Chain | H15: BSE South Chain | I15: BSE South Chain | J15: - | K15: - | L15: - | M15: ไม่ได้รับการตรวจ
B16: 11 | C16: 24355-61 | D16: นาง กาญจนา ลีลารุจนกุล | E16: 13 ต.ค. 2535 | F16: 31 | G16: BSE Operation Officer-STS | H16: BSE Operation - STS | I16: BSE Operation - STS | J16: - | K16: - | L16: - | M16: ไม่ได้รับการตรวจ
B17: 12 | C17: 11655-54 | D17: นาย ก้าน สิทธิวงศ์ | E17: 28 ก.ค. 2525 | F17: 41 | G17: พนักงานผลิตถุงกระดาษ | H17: ผลิตถุงกระดาษ | I17: Operations | J17: 27 | K17: 28 | L17: 58 | M17: ปกติ
B18: 13 | C18: 4482-62 | D18: นาย กิตตินันท์ จันทกูล | E18: 27 ก.ย. 2534 | F18: 32 | G18: Mechanical Technician | H18: Plant Maintenance | I18: Maintenance Repair Overhaul - STS | J18: 35 | K18: 77 | L18: 93 | M18: ผิดปกติ
B19: 14 | C19: 16852-60 | D19: นาย กิตติพงศ์ ไพชำนาญ | E19: 04 มี.ค. 2535 | F19: 32 | G19: Engineer | H19: Maintenance Repair Overhaul - STS | I19: Maintenance Repair Overhaul - STS | J19: 26 | K19: 19 | L19: 79 | M19: ปกติ
B20: 15 | C20: 22376-59 | D20: นาย กิตติพงศ์ สหกโร | E20: 30 เม.ย. 2530 | F20: 37 | G20: พนักงานควบคุมเครื่องย่อย | H20: ผลิตหินย่อยและหินก่อสร้าง | I20: Quarry | J20: 51 | K20: 85 | L20: 63 | M20: ผิดปกติ
B21: 16 | C21: 3969-43 | D21: นาย กิตติพงษ์ คงปลอด | E21: 02 ก.พ. 2520 | F21: 47 | G21: Mechanical Technician | H21: Plant Maintenance | I21: Maintenance Repair Overhaul - STS | J21: 23 | K21: 19 | L21: 82 | M21: ปกติ
B22: 17 | C22: 6256-66 | D22: นาย กิตติพงษ์ ดอกไม้ทอง | E22: 27 ก.ค. 2541 | F22: 25 | G22: #N/A | H22: #N/A | I22: #N/A | J22: 23 | K22: 24 | L22: 72 | M22: ปกติ
B23: 18 | C23: 24617-61 | D23: นาย กิตติพงษ์ ทองมี | E23: 20 เม.ย. 2535 | F23: 32 | G23: #N/A | H23: #N/A | I23: #N/A | J23: 22 | K23: 16 | L23: 63 | M23: ปกติ
B24: 19 | C24: 22368-59 | D24: นาย กิตติศักดิ์ ช้างกลาง | E24: 14 ก.พ. 2535 | F24: 32 | G24: พนักงานควบคุมจักรกลหนัก | H24: วางแผนและพัฒนาเหมือง | I24: Quarry | J24: 26 | K24: 12 | L24: 62 | M24: ปกติ
B25: 20 | C25: 22377-59 | D25: นาย กิตติศักดิ์ อ่วมคง | E25: 22 ส.ค. 2531 | F25: 35 | G25: พนักงานควบคุมเครื่องย่อย | H25: ผลิตหินย่อยและหินก่อสร้าง | I25: Quarry | J25: 26 | K25: 25 | L25: 80 | M25: ปกติ
B26: 21 | C26: 22436-59 | D26: นาย กิตติ ศิริพันธุ์ | E26: 29 มิ.ย. 2529 | F26: 38 | G26: พนักงานเหมืองแร่ | H26: จัดหาและเตรียมวัตถุดิบ | I26: Quarry | J26: 34 | K26: 34 | L26: 72 | M26: ปกติ
B27: 22 | C27: 4570-62 | D27: นาย กีรติ ทับทอง | E27: 11 พ.ค. 2531 | F27: 36 | G27: พนักงาน AFR | H27: AFR | I27: Operations | J27: 18 | K27: 14 | L27: 106 | M27: ปกติ
B28: 23 | C28: 24218-61 | D28: นาง กุลธิดา เครือสาย | E28: 27 มิ.ย. 2516 | F28: 51 | G28: พนักงานบริการลูกค้า | H28: บริการลูกค้า | I28: Operations | J28: 26 | K28: 37 | L28: - | M28: ผิดปกติ
B29: 24 | C29: 19923-62 | D29: นาย เกรียงไกร คุณโลก | E29: 14 ธ.ค. 2513 | F29: 53 | G29: #N/A | H29: #N/A | I29: #N/A | J29: 38 | K29: 42 | L29: 66 | M29: ปกติ
B30: 25 | C30: 9075-50 | D30: นาย เกรียงไกร เซ่งเซี่ยง | E30: 25 เม.ย. 2527 | F30: 40 | G30: Mechanical Technician | H30: Plant Maintenance | I30: Maintenance Repair Overhaul - STS | J30: 24 | K30: 20 | L30: 72 | M30: ปกติ
B31: 26 | C31: 6253-66 | D31: นาย เกรียงไกร ธรรมโกศล | E31: 20 ธ.ค. 2536 | F31: 30 | G31: #N/A | H31: #N/A | I31: #N/A | J31: 20 | K31: 20 | L31: 74 | M31: ปกติ
B32: 27 | C32: 19837-62 | D32: นาย เกรียงศักดิ์ ชูดวงจันทร์ | E32: 11 มี.ค. 2526 | F32: 41 | G32: #N/A | H32: #N/A | I32: #N/A | J32: 21 | K32: 13 | L32: 99 | M32: ปกติ
B33: 28 | C33: 20003-62 | D33: นาย เกียรติศักดิ์ ทองทิพย์ | E33: 03 ก.ย. 2516 | F33: 50 | G33: #N/A | H33: #N/A | I33: #N/A | J33: 35 | K33: 13 | L33: 64 | M33: ปกติ
B34: 29 | C34: 17784-56 | D34: นาย เกียรติศักดิ์ ไสยฉิม | E34: 14 ม.ค. 2520 | F34: 47 | G34: พนักงานควบคุมจักรกลหนัก | H34: วางแผนและพัฒนาเหมือง | I34: Quarry | J34: - | K34: - | L34: - | M34: ไม่ได้รับการตรวจ
B35: 30 | C35: 24161-61 | D35: นาย โกมิน บวรศุภศรี | E35: 12 ส.ค. 2537 | F35: 29 | G35: Measurement and Analysis Technician | H35: Measurement and Analysis | I35: Maintenance Repair Overhaul - STS | J35: 29 | K35: 37 | L35: 56 | M35: ปกติ
B36: 31 | C36: 7408-51 | D36: นาย โกสินทร์ ศิริปทาวานิช | E36: 03 ต.ค. 2511 | F36: 55 | G36: ผู้ช่วยผู้จัดการตักและขนส่ง | H36: ผลิตหินก่อนย่อย | I36: Quarry | J36: - | K36: - | L36: - | M36: ไม่ได้รับการตรวจ
B37: 32 | C37: 4362-62 | D37: นาย ไกรศรี ผาสุข | E37: 27 พ.ค. 2515 | F37: 52 | G37: #N/A | H37: #N/A | I37: #N/A | J37: 21 | K37: 44 | L37: 66 | M37: ปกติ
B38: 33 | C38: 14885-56 | D38: นาย ไกวัล มวยดี | E38: 02 ก.พ. 2526 | F38: 41 | G38: Measurement and Analysis Technician | H38: Measurement and Analysis | I38: Maintenance Repair Overhaul - STS | J38: 30 | K38: 21 | L38: 71 | M38: ปกติ
B39: 34 | C39: 4216-61 | D39: นาย ขจรพงศ์ สุวรรณเพ็ชร | E39: 05 เม.ย. 2536 | F39: 31 | G39: พนักงาน Fuel & Export | H39: Fuel and Export | I39: Operations | J39: 41 | K39: 83 | L39: 115 | M39: ผิดปกติ
B40: 35 | C40: 11762-64 | D40: น.ส. ขวัญวดี อามิตย์ | E40: 13 พ.ย. 2531 | F40: 35 | G40: #N/A | H40: #N/A | I40: #N/A | J40: 23 | K40: 24 | L40: 55 | M40: ปกติ
B41: 36 | C41: 25972-60 | D41: นาย คงศักย์ มูลจันทะ | E41: 06 ก.พ. 2510 | F41: 57 | G41: #N/A | H41: #N/A | I41: #N/A | J41: 39 | K41: 49 | L41: 53 | M41: ปกติ
B42: 37 | C42: 13651-51 | D42: นาย คณากร สังข์ทอง | E42: 27 ส.ค. 2530 | F42: 36 | G42: Electrical Technician | H42: Plant Maintenance | I42: Maintenance Repair Overhaul - STS | J42: - | K42: - | L42: - | M42: ไม่ได้รับการตรวจ
...

Sheet การทำงานของไต
B1: ผลการตรวจการทำงานของไต (BUN,Creatinine)
B3: No | C3: HN | D3: ชื่อ - สกุล | E3: วัน/เดือน/ปีเกิด | F3: อายุ | G3: ตำแหน่งงาน | H3: หน่วยงาน | I3: ส่วน (สำหรับพนักงาน) | J3: การทำงานของไต(BUN) | K3: การทำงานของไต(Creatinine) | L3: สรุปผลการตรวจ
J5: ช ค่าปกติ 9 - 20 ,ญ ค่าปกติ 7-17 | K5: ช ค่าปกติ 0.66 - 1.25 mg/dL
K6: ญ ค่าปกติ 0.52 - 1.04 mg/dL
B7: 1 | C7: 14471-58 | D7: นาง กมลทิพย์ ขบวนสาร | E7: 07 มิ.ย. 2527 | F7: 40 | G7: พนักงานธุรการ | H7: Operations | I7: Operations | J7: - | K7: - | L7: ไม่ได้รับการตรวจ | N7: การทำงานของไต
B8: 2 | C8: 165-57 | D8: นาย กรณัฐพงษ์ เรืองระพีพรรณ | E8: 04 เม.ย. 2533 | F8: 34 | G8: #N/A | H8: #N/A | I8: #N/A | J8: 18.6 | K8: 1.20 | L8: ปกติ | N8: ปกติ | O8: 381
B9: 3 | C9: 9043-49 | D9: น.ส. กฤติกา หมัดโส๊ะ | E9: 01 ม.ค. 2528 | F9: 39 | G9: พนักงานเทคโนโลยีสารสนเทศ | H9: เทคโนโลยีสารสนเทศ | I9: MD Office | J9: - | K9: - | L9: ไม่ได้รับการตรวจ | N9: ผิดปกติ | O9: 33
B10: 4 | C10: 5101-50 | D10: นาย กฤษฎากรณ์ เดชะราช | E10: 18 มิ.ย. 2515 | F10: 52 | G10: Technical and Maintenance Planning Manager | H10: Plant Maintenance | I10: Maintenance Repair Overhaul - STS | J10: - | K10: - | L10: ไม่ได้รับการตรวจ | N10: รวม | O10: 414
B11: 5 | C11: 13350-56 | D11: นาย กฤษณรักษ์ รัตนะ | E11: 12 พ.ย. 2530 | F11: 36 | G11: พนักงานซ่อมบำรุงจักรกลหนัก | H11: ซ่อมบำรุงจักรกลหนัก | I11: Quarry | J11: 11.7 | K11: 0.97 | L11: ปกติ
B12: 6 | C12: 20669-60 | D12: นาย กฤษดา หนูหอ | E12: 25 เม.ย. 2520 | F12: 47 | G12: Maintenance Overhaul and Consultancy Technician - Electrical | H12: Maintenance Overhaul and Consultancy - Electrical | I12: Maintenance Repair Overhaul - STS | J12: 13.3 | K12: 1.47 | L12: ผิดปกติ
B13: 7 | C13: 20050-65 | D13: นาย กวิศ แซ่ตั้ง | E13: 01 ม.ค. 2535 | F13: 32 | G13: #N/A | H13: #N/A | I13: #N/A | J13: 12.0 | K13: 1.05 | L13: ปกติ
B14: 8 | C14: 11980-47 | D14: นาย ก้องทัย คุณโลก | E14: 17 มี.ค. 2512 | F14: 55 | G14: Mechanical Maintenance Manager – Clinker | H14: Plant Maintenance | I14: Maintenance Repair Overhaul - STS | J14: 12.3 | K14: 1.00 | L14: ปกติ
B15: 9 | C15: 443-50 | D15: นาย กัญจน์ภัสสรณ์ พรหมแสง | E15: 05 มิ.ย. 2519 | F15: 48 | G15: #N/A | H15: #N/A | I15: #N/A | J15: 11.9 | K15: 1.15 | L15: ปกติ
B16: 10 | C16: 19597-49 | D16: น.ส. กัญธนัช ศรีโยธา | E16: 14 ต.ค. 2528 | F16: 38 | G16: BSE Assistant Manager-South Chain | H16: BSE South Chain | I16: BSE South Chain | J16: - | K16: - | L16: ไม่ได้รับการตรวจ
B17: 11 | C17: 24355-61 | D17: นาง กาญจนา ลีลารุจนกุล | E17: 13 ต.ค. 2535 | F17: 31 | G17: BSE Operation Officer-STS | H17: BSE Operation - STS | I17: BSE Operation - STS | J17: - | K17: - | L17: ไม่ได้รับการตรวจ
B18: 12 | C18: 11655-54 | D18: นาย ก้าน สิทธิวงศ์ | E18: 28 ก.ค. 2525 | F18: 41 | G18: พนักงานผลิตถุงกระดาษ | H18: ผลิตถุงกระดาษ | I18: Operations | J18: 11.6 | K18: 1.19 | L18: ปกติ
B19: 13 | C19: 4482-62 | D19: นาย กิตตินันท์ จันทกูล | E19: 27 ก.ย. 2534 | F19: 32 | G19: Mechanical Technician | H19: Plant Maintenance | I19: Maintenance Repair Overhaul - STS | J19: 13.5 | K19: 0.89 | L19: ปกติ
B20: 14 | C20: 16852-60 | D20: นาย กิตติพงศ์ ไพชำนาญ | E20: 04 มี.ค. 2535 | F20: 32 | G20: Engineer | H20: Maintenance Repair Overhaul - STS | I20: Maintenance Repair Overhaul - STS | J20: 10.9 | K20: 0.92 | L20: ปกติ
B21: 15 | C21: 22376-59 | D21: นาย กิตติพงศ์ สหกโร | E21: 30 เม.ย. 2530 | F21: 37 | G21: พนักงานควบคุมเครื่องย่อย | H21: ผลิตหินย่อยและหินก่อสร้าง | I21: Quarry | J21: 13.4 | K21: 0.77 | L21: ปกติ
B22: 16 | C22: 3969-43 | D22: นาย กิตติพงษ์ คงปลอด | E22: 02 ก.พ. 2520 | F22: 47 | G22: Mechanical Technician | H22: Plant Maintenance | I22: Maintenance Repair Overhaul - STS | J22: 12.5 | K22: 1.01 | L22: ปกติ
B23: 17 | C23: 6256-66 | D23: นาย กิตติพงษ์ ดอกไม้ทอง | E23: 27 ก.ค. 2541 | F23: 25 | G23: #N/A | H23: #N/A | I23: #N/A | J23: 11.6 | K23: 0.82 | L23: ปกติ
B24: 18 | C24: 24617-61 | D24: นาย กิตติพงษ์ ทองมี | E24: 20 เม.ย. 2535 | F24: 32 | G24: #N/A | H24: #N/A | I24: #N/A | J24: 8.7 | K24: 1.13 | L24: ปกติ
B25: 19 | C25: 22368-59 | D25: นาย กิตติศักดิ์ ช้างกลาง | E25: 14 ก.พ. 2535 | F25: 32 | G25: พนักงานควบคุมจักรกลหนัก | H25: วางแผนและพัฒนาเหมือง | I25: Quarry | J25: 13.5 | K25: 0.91 | L25: ปกติ
B26: 20 | C26: 22377-59 | D26: นาย กิตติศักดิ์ อ่วมคง | E26: 22 ส.ค. 2531 | F26: 35 | G26: พนักงานควบคุมเครื่องย่อย | H26: ผลิตหินย่อยและหินก่อสร้าง | I26: Quarry | J26: 14.0 | K26: 0.97 | L26: ปกติ
B27: 21 | C27: 22436-59 | D27: นาย กิตติ ศิริพันธุ์ | E27: 29 มิ.ย. 2529 | F27: 38 | G27: พนักงานเหมืองแร่ | H27: จัดหาและเตรียมวัตถุดิบ | I27: Quarry | J27: 12.8 | K27: 1.19 | L27: ปกติ
B28: 22 | C28: 4570-62 | D28: นาย กีรติ ทับทอง | E28: 11 พ.ค. 2531 | F28: 36 | G28: พนักงาน AFR | H28: AFR | I28: Operations | J28: 10.5 | K28: 0.95 | L28: ปกติ
B29: 23 | C29: 24218-61 | D29: นาง กุลธิดา เครือสาย | E29: 27 มิ.ย. 2516 | F29: 51 | G29: พนักงานบริการลูกค้า | H29: บริการลูกค้า | I29: Operations | J29: - | K29: 0.69 | L29: ปกติ
B30: 24 | C30: 19923-62 | D30: นาย เกรียงไกร คุณโลก | E30: 14 ธ.ค. 2513 | F30: 53 | G30: #N/A | H30: #N/A | I30: #N/A | J30: 15.5 | K30: 0.99 | L30: ปกติ
B31: 25 | C31: 9075-50 | D31: นาย เกรียงไกร เซ่งเซี่ยง | E31: 25 เม.ย. 2527 | F31: 40 | G31: Mechanical Technician | H31: Plant Maintenance | I31: Maintenance Repair Overhaul - STS | J31: 15.5 | K31: 1.02 | L31: ปกติ
B32: 26 | C32: 6253-66 | D32: นาย เกรียงไกร ธรรมโกศล | E32: 20 ธ.ค. 2536 | F32: 30 | G32: #N/A | H32: #N/A | I32: #N/A | J32: 12.8 | K32: 0.87 | L32: ปกติ
B33: 27 | C33: 19837-62 | D33: นาย เกรียงศักดิ์ ชูดวงจันทร์ | E33: 11 มี.ค. 2526 | F33: 41 | G33: #N/A | H33: #N/A | I33: #N/A | J33: 9.1 | K33: 0.97 | L33: ปกติ
B34: 28 | C34: 20003-62 | D34: นาย เกียรติศักดิ์ ทองทิพย์ | E34: 03 ก.ย. 2516 | F34: 50 | G34: #N/A | H34: #N/A | I34: #N/A | J34: 12.4 | K34: 1.05 | L34: ปกติ
B35: 29 | C35: 17784-56 | D35: นาย เกียรติศักดิ์ ไสยฉิม | E35: 14 ม.ค. 2520 | F35: 47 | G35: พนักงานควบคุมจักรกลหนัก | H35: วางแผนและพัฒนาเหมือง | I35: Quarry | J35: - | K35: - | L35: ไม่ได้รับการตรวจ
B36: 30 | C36: 24161-61 | D36: นาย โกมิน บวรศุภศรี | E36: 12 ส.ค. 2537 | F36: 29 | G36: Measurement and Analysis Technician | H36: Measurement and Analysis | I36: Maintenance Repair Overhaul - STS | J36: 10.9 | K36: 0.94 | L36: ปกติ
B37: 31 | C37: 7408-51 | D37: นาย โกสินทร์ ศิริปทาวานิช | E37: 03 ต.ค. 2511 | F37: 55 | G37: ผู้ช่วยผู้จัดการตักและขนส่ง | H37: ผลิตหินก่อนย่อย | I37: Quarry | J37: - | K37: - | L37: ไม่ได้รับการตรวจ
B38: 32 | C38: 4362-62 | D38: นาย ไกรศรี ผาสุข | E38: 27 พ.ค. 2515 | F38: 52 | G38: #N/A | H38: #N/A | I38: #N/A | J38: 14.9 | K38: 0.84 | L38: ปกติ
B39: 33 | C39: 14885-56 | D39: นาย ไกวัล มวยดี | E39: 02 ก.พ. 2526 | F39: 41 | G39: Measurement and Analysis Technician | H39: Measurement and Analysis | I39: Maintenance Repair Overhaul - STS | J39: 15.2 | K39: 1.28 | L39: ผิดปกติ
B40: 34 | C40: 4216-61 | D40: นาย ขจรพงศ์ สุวรรณเพ็ชร | E40: 05 เม.ย. 2536 | F40: 31 | G40: พนักงาน Fuel & Export | H40: Fuel and Export | I40: Operations | J40: 14.2 | K40: 1.04 | L40: ปกติ
B41: 35 | C41: 11762-64 | D41: น.ส. ขวัญวดี อามิตย์ | E41: 13 พ.ย. 2531 | F41: 35 | G41: #N/A | H41: #N/A | I41: #N/A | J41: 11.9 | K41: 0.69 | L41: ปกติ
B42: 36 | C42: 25972-60 | D42: นาย คงศักย์ มูลจันทะ | E42: 06 ก.พ. 2510 | F42: 57 | G42: #N/A | H42: #N/A | I42: #N/A | J42: 17.4 | K42: 1.06 | L42: ปกติ
...

Sheet กรดยูริคในเลือดUric
B1: ผลการตรวจกรดยูริคในเลือด (Uric Acid)
B3: No | C3: HN | D3: ชื่อ - สกุล | E3: วัน/เดือน/ปีเกิด | F3: อายุ | G3: ตำแหน่งงาน | H3: หน่วยงาน | I3: ส่วน (สำหรับพนักงาน) | J3: กรดยูริคในเลือด(Uric Acid) | K3: สรุปผลการตรวจ
J4: ญ ค่าปกติ 2.5-6.2 mg/dl
J5: ช ค่าปกติ 3.5-8.5 mg/dl
B6: 1 | C6: 14471-58 | D6: นาง กมลทิพย์ ขบวนสาร | E6: 07 มิ.ย. 2527 | F6: 40 | G6: พนักงานธุรการ | H6: Operations | I6: Operations | J6: - | K6: ไม่ได้รับการตรวจ | M6: กรดยูริคในเลือด
B7: 2 | C7: 165-57 | D7: นาย กรณัฐพงษ์ เรืองระพีพรรณ | E7: 04 เม.ย. 2533 | F7: 34 | G7: #N/A | H7: #N/A | I7: #N/A | J7: - | K7: ไม่ได้รับการตรวจ | M7: ปกติ | N7: 41
B8: 3 | C8: 9043-49 | D8: น.ส. กฤติกา หมัดโส๊ะ | E8: 01 ม.ค. 2528 | F8: 39 | G8: พนักงานเทคโนโลยีสารสนเทศ | H8: เทคโนโลยีสารสนเทศ | I8: MD Office | J8: - | K8: ไม่ได้รับการตรวจ | M8: ผิดปกติ | N8: 1
B9: 4 | C9: 5101-50 | D9: นาย กฤษฎากรณ์ เดชะราช | E9: 18 มิ.ย. 2515 | F9: 52 | G9: Technical and Maintenance Planning Manager | H9: Plant Maintenance | I9: Maintenance Repair Overhaul - STS | J9: - | K9: ไม่ได้รับการตรวจ | M9: รวม | N9: 42
B10: 5 | C10: 13350-56 | D10: นาย กฤษณรักษ์ รัตนะ | E10: 12 พ.ย. 2530 | F10: 36 | G10: พนักงานซ่อมบำรุงจักรกลหนัก | H10: ซ่อมบำรุงจักรกลหนัก | I10: Quarry | J10: - | K10: ไม่ได้รับการตรวจ
B11: 6 | C11: 20669-60 | D11: นาย กฤษดา หนูหอ | E11: 25 เม.ย. 2520 | F11: 47 | G11: Maintenance Overhaul and Consultancy Technician - Electrical | H11: Maintenance Overhaul and Consultancy - Electrical | I11: Maintenance Repair Overhaul - STS | J11: - | K11: ไม่ได้รับการตรวจ
B12: 7 | C12: 20050-65 | D12: นาย กวิศ แซ่ตั้ง | E12: 01 ม.ค. 2535 | F12: 32 | G12: #N/A | H12: #N/A | I12: #N/A | J12: - | K12: ไม่ได้รับการตรวจ
B13: 8 | C13: 11980-47 | D13: นาย ก้องทัย คุณโลก | E13: 17 มี.ค. 2512 | F13: 55 | G13: Mechanical Maintenance Manager – Clinker | H13: Plant Maintenance | I13: Maintenance Repair Overhaul - STS | J13: - | K13: ไม่ได้รับการตรวจ
B14: 9 | C14: 443-50 | D14: นาย กัญจน์ภัสสรณ์ พรหมแสง | E14: 05 มิ.ย. 2519 | F14: 48 | G14: #N/A | H14: #N/A | I14: #N/A | J14: - | K14: ไม่ได้รับการตรวจ
B15: 10 | C15: 19597-49 | D15: น.ส. กัญธนัช ศรีโยธา | E15: 14 ต.ค. 2528 | F15: 38 | G15: BSE Assistant Manager-South Chain | H15: BSE South Chain | I15: BSE South Chain | J15: - | K15: ไม่ได้รับการตรวจ
B16: 11 | C16: 24355-61 | D16: นาง กาญจนา ลีลารุจนกุล | E16: 13 ต.ค. 2535 | F16: 31 | G16: BSE Operation Officer-STS | H16: BSE Operation - STS | I16: BSE Operation - STS | J16: - | K16: ไม่ได้รับการตรวจ
B17: 12 | C17: 11655-54 | D17: นาย ก้าน สิทธิวงศ์ | E17: 28 ก.ค. 2525 | F17: 41 | G17: พนักงานผลิตถุงกระดาษ | H17: ผลิตถุงกระดาษ | I17: Operations | J17: 8.5 | K17: ปกติ
B18: 13 | C18: 4482-62 | D18: นาย กิตตินันท์ จันทกูล | E18: 27 ก.ย. 2534 | F18: 32 | G18: Mechanical Technician | H18: Plant Maintenance | I18: Maintenance Repair Overhaul - STS | J18: - | K18: ไม่ได้รับการตรวจ
B19: 14 | C19: 16852-60 | D19: นาย กิตติพงศ์ ไพชำนาญ | E19: 04 มี.ค. 2535 | F19: 32 | G19: Engineer | H19: Maintenance Repair Overhaul - STS | I19: Maintenance Repair Overhaul - STS | J19: - | K19: ไม่ได้รับการตรวจ
B20: 15 | C20: 22376-59 | D20: นาย กิตติพงศ์ สหกโร | E20: 30 เม.ย. 2530 | F20: 37 | G20: พนักงานควบคุมเครื่องย่อย | H20: ผลิตหินย่อยและหินก่อสร้าง | I20: Quarry | J20: 5.9 | K20: ปกติ
B21: 16 | C21: 3969-43 | D21: นาย กิตติพงษ์ คงปลอด | E21: 02 ก.พ. 2520 | F21: 47 | G21: Mechanical Technician | H21: Plant Maintenance | I21: Maintenance Repair Overhaul - STS | J21: - | K21: ไม่ได้รับการตรวจ
B22: 17 | C22: 6256-66 | D22: นาย กิตติพงษ์ ดอกไม้ทอง | E22: 27 ก.ค. 2541 | F22: 25 | G22: #N/A | H22: #N/A | I22: #N/A | J22: - | K22: ไม่ได้รับการตรวจ
B23: 18 | C23: 24617-61 | D23: นาย กิตติพงษ์ ทองมี | E23: 20 เม.ย. 2535 | F23: 32 | G23: #N/A | H23: #N/A | I23: #N/A | J23: - | K23: ไม่ได้รับการตรวจ
B24: 19 | C24: 22368-59 | D24: นาย กิตติศักดิ์ ช้างกลาง | E24: 14 ก.พ. 2535 | F24: 32 | G24: พนักงานควบคุมจักรกลหนัก | H24: วางแผนและพัฒนาเหมือง | I24: Quarry | J24: - | K24: ไม่ได้รับการตรวจ
B25: 20 | C25: 22377-59 | D25: นาย กิตติศักดิ์ อ่วมคง | E25: 22 ส.ค. 2531 | F25: 35 | G25: พนักงานควบคุมเครื่องย่อย | H25: ผลิตหินย่อยและหินก่อสร้าง | I25: Quarry | J25: - | K25: ไม่ได้รับการตรวจ
B26: 21 | C26: 22436-59 | D26: นาย กิตติ ศิริพันธุ์ | E26: 29 มิ.ย. 2529 | F26: 38 | G26: พนักงานเหมืองแร่ | H26: จัดหาและเตรียมวัตถุดิบ | I26: Quarry | J26: - | K26: ไม่ได้รับการตรวจ
B27: 22 | C27: 4570-62 | D27: นาย กีรติ ทับทอง | E27: 11 พ.ค. 2531 | F27: 36 | G27: พนักงาน AFR | H27: AFR | I27: Operations | J27: - | K27: ไม่ได้รับการตรวจ
B28: 23 | C28: 24218-61 | D28: นาง กุลธิดา เครือสาย | E28: 27 มิ.ย. 2516 | F28: 51 | G28: พนักงานบริการลูกค้า | H28: บริการลูกค้า | I28: Operations | J28: 5.5 | K28: ปกติ
B29: 24 | C29: 19923-62 | D29: นาย เกรียงไกร คุณโลก | E29: 14 ธ.ค. 2513 | F29: 53 | G29: #N/A | H29: #N/A | I29: #N/A | J29: 7.6 | K29: ปกติ
B30: 25 | C30: 9075-50 | D30: นาย เกรียงไกร เซ่งเซี่ยง | E30: 25 เม.ย. 2527 | F30: 40 | G30: Mechanical Technician | H30: Plant Maintenance | I30: Maintenance Repair Overhaul - STS | J30: - | K30: ไม่ได้รับการตรวจ
B31: 26 | C31: 6253-66 | D31: นาย เกรียงไกร ธรรมโกศล | E31: 20 ธ.ค. 2536 | F31: 30 | G31: #N/A | H31: #N/A | I31: #N/A | J31: - | K31: ไม่ได้รับการตรวจ
B32: 27 | C32: 19837-62 | D32: นาย เกรียงศักดิ์ ชูดวงจันทร์ | E32: 11 มี.ค. 2526 | F32: 41 | G32: #N/A | H32: #N/A | I32: #N/A | J32: - | K32: ไม่ได้รับการตรวจ
B33: 28 | C33: 20003-62 | D33: นาย เกียรติศักดิ์ ทองทิพย์ | E33: 03 ก.ย. 2516 | F33: 50 | G33: #N/A | H33: #N/A | I33: #N/A | J33: - | K33: ไม่ได้รับการตรวจ
B34: 29 | C34: 17784-56 | D34: นาย เกียรติศักดิ์ ไสยฉิม | E34: 14 ม.ค. 2520 | F34: 47 | G34: พนักงานควบคุมจักรกลหนัก | H34: วางแผนและพัฒนาเหมือง | I34: Quarry | J34: - | K34: ไม่ได้รับการตรวจ
B35: 30 | C35: 24161-61 | D35: นาย โกมิน บวรศุภศรี | E35: 12 ส.ค. 2537 | F35: 29 | G35: Measurement and Analysis Technician | H35: Measurement and Analysis | I35: Maintenance Repair Overhaul - STS | J35: - | K35: ไม่ได้รับการตรวจ
B36: 31 | C36: 7408-51 | D36: นาย โกสินทร์ ศิริปทาวานิช | E36: 03 ต.ค. 2511 | F36: 55 | G36: ผู้ช่วยผู้จัดการตักและขนส่ง | H36: ผลิตหินก่อนย่อย | I36: Quarry | J36: - | K36: ไม่ได้รับการตรวจ
B37: 32 | C37: 4362-62 | D37: นาย ไกรศรี ผาสุข | E37: 27 พ.ค. 2515 | F37: 52 | G37: #N/A | H37: #N/A | I37: #N/A | J37: - | K37: ไม่ได้รับการตรวจ
